Workbook

Sheet Start Here
A1: Teacher Command Center
A2: Plan the term, grade it, and see who needs help - all tabs work together.
B4: What is linked to what
B5: Pacing plan > Assignments get their due dates > Gradebook knows what is due > submission rate, missing work,
B6: grades and class standing update by themselves > Dashboard and Student Report show the result.
B8: Set up in 15 minutes
B9: 1. Setup: class name, the Monday your term starts, category weights and grade scale.
B10: 2. Roster: type your students (up to 40).
B11: 3. Pacing: list your units with a start week and length. The timeline colors itself.
B12: 4. Assignments: pick the unit for each assignment. It is due at the end of that unit unless you type a date.
B13: 5. Gradebook: enter scores. Type M for missing, EX for excused. Past-due blanks count as missing.
B15: What you get
B16: Dashboard: class average, submission rate, students at risk, grade spread, workload per week.
B17: Standings: each student's grade, submission rate and a combined performance index with rank and percentile,
... B39: Version 2.0

Sheet Dashboard
A1: Dashboard
A2: =Setup!B4&" | "&Setup!B5&" | as of "&TEXT(Setup!B8,"mmm d, yyyy")&" | week "&Pacing!C3&" of "&Setup!B7
B4: Class average | E4: Work turned in | H4: Students at risk
B5: =IFERROR(AVERAGE(Gradebook!C10:C49),"") | E5: =IFERROR(AVERAGE(Gradebook!E10:E49),"") | H5: =COUNTIF(Standings!K8:K47,"At risk")
B6: =COUNT(Gradebook!C10:C49)&" students graded" | E6: ="Missing items: "&SUM(Gradebook!F10:F49) | H6: =COUNTIF(Standings!K8:K47,"Watch")&" more to watch"
B8: Grade spread | E8: Turned in vs. score | H8: Needs attention (lowest index) | K8: Grade | L8: Students
H9: Student | I9: Index | K9: A | L9: =COUNTIF(Gradebook!D10:D49,"A*")
H10: =IF((COUNT(Standings!$F$8:$F$47)-0)<1,"",INDEX(Standings!$B$8:$B$47,MATCH((COUNT(Standings!$F$8:$F$47)-0),Standings!$M$8:$M$47,0))) | I10: =IF((COUNT(Standings!$F$8:$F$47)-0)<1,"",INDEX(Standings!$F$8:$F$47,MATCH((COUNT(Standings!$F$8:$F$47)-0),Standings!$M$8:$M$47,0))) | K10: B | L10: =COUNTIF(Gradebook!D10:D49,"B*")
H11: =IF((COUNT(Standings!$F$8:$F$47)-1)<1,"",INDEX(Standings!$B$8:$B$47,MATCH((COUNT(Standings!$F$8:$F$47)-1),Standings!$M$8:$M$47,0))) | I11: =IF((COUNT(Standings!$F$8:$F$47)-1)<1,"",INDEX(Standings!$F$8:$F$47,MATCH((COUNT(Standings!$F$8:$F$47)-1),Standings!$M$8:$M$47,0))) | K11: C | L11: =COUNTIF(Gradebook!D10:D49,"C*")
H12: =IF((COUNT(Standings!$F$8:$F$47)-2)<1,"",INDEX(Standings!$B$8:$B$47,MATCH((COUNT(Standings!$F$8:$F$47)-2),Standings!$M$8:$M$47,0))) | I12: =IF((COUNT(Standings!$F$8:$F$47)-2)<1,"",INDEX(Standings!$F$8:$F$47,MATCH((COUNT(Standings!$F$8:$F$47)-2),Standings!$M$8:$M$47,0))) | K12: D | L12: =COUNTIF(Gradebook!D10:D49,"D*")
H13: =IF((COUNT(Standings!$F$8:$F$47)-3)<1,"",INDEX(Standings!$B$8:$B$47,MATCH((COUNT(Standings!$F$8:$F$47)-3),Standings!$M$8:$M$47,0))) | I13: =IF((COUNT(Standings!$F$8:$F$47)-3)<1,"",INDEX(Standings!$F$8:$F$47,MATCH((COUNT(Standings!$F$8:$F$47)-3),Standings!$M$8:$M$47,0))) | K13: F | L13: =COUNTIF(Gradebook!D10:D49,"F*")
H14: =IF((COUNT(Standings!$F$8:$F$47)-4)<1,"",INDEX(Standings!$B$8:$B$47,MATCH((COUNT(Standings!$F$8:$F$47)-4),Standings!$M$8:$M$47,0))) | I14: =IF((COUNT(Standings!$F$8:$F$47)-4)<1,"",INDEX(Standings!$F$8:$F$47,MATCH((COUNT(Standings!$F$8:$F$47)-4),Standings!$M$8:$M$47,0)))
H15: =IF((COUNT(Standings!$F$8:$F$47)-5)<1,"",INDEX(Standings!$B$8:$B$47,MATCH((COUNT(Standings!$F$8:$F$47)-5),Standings!$M$8:$M$47,0))) | I15: =IF((COUNT(Standings!$F$8:$F$47)-5)<1,"",INDEX(Standings!$F$8:$F$47,MATCH((COUNT(Standings!$F$8:$F$47)-5),Standings!$M$8:$M$47,0)))
H16: =IF((COUNT(Standings!$F$8:$F$47)-6)<1,"",INDEX(Standings!$B$8:$B$47,MATCH((COUNT(Standings!$F$8:$F$47)-6),Standings!$M$8:$M$47,0))) | I16: =IF((COUNT(Standings!$F$8:$F$47)-6)<1,"",INDEX(Standings!$F$8:$F$47,MATCH((COUNT(Standings!$F$8:$F$47)-6),Standings!$M$8:$M$47,0)))
H17: =IF((COUNT(Standings!$F$8:$F$47)-7)<1,"",INDEX(Standings!$B$8:$B$47,MATCH((COUNT(Standings!$F$8:$F$47)-7),Standings!$M$8:$M$47,0))) | I17: =IF((COUNT(Standings!$F$8:$F$47)-7)<1,"",INDEX(Standings!$F$8:$F$47,MATCH((COUNT(Standings!$F$8:$F$47)-7),Standings!$M$8:$M$47,0)))
K20: =Setup!B27
B23: Workload by week (assignments due)

Sheet Setup
A1: Setup
A2: Fill the white cells once at the start of the term.
A4: Class | B4: Period 3 - Algebra I
A5: Teacher | B5: Ms. Rivera
A6: Term starts (Monday) | B6: 46251
A7: Weeks in the term | B7: 18
A8: As of (leave =TODAY() or type a date) | B8: =TODAY()
A9: Count past-due blanks as 0? | B9: Yes
A11: Category | B11: Weight | D11: Min % | E11: Grade | G11: Percentile from | H11: Curved grade
A12: Homework | B12: 0.2 | D12: 0 | E12: F | G12: 0 | H12: F
A13: Quizzes | B13: 0.2 | D13: 0.6 | E13: D- | G13: 0.05 | H13: D
A14: Tests | B14: 0.4 | D14: 0.63 | E14: D | G14: 0.2 | H14: C
A15: Projects | B15: 0.1 | D15: 0.67 | E15: D+ | G15: 0.55 | H15: B
A16: Participation | B16: 0.1 | D16: 0.7 | E16: C- | G16: 0.85 | H16: A
A17: Total | B17: =SUM(B12:B16) | D17: 0.73 | E17: C | G17: Optional relative grading.
A18: =IF(ROUND(B17,4)=1,"Weights add up to 100%.","Check: weights add up to "&TEXT(B17,"0%")&".") | D18: 0.77 | E18: C+ | G18: Default: top 15% A, next 30% B,
D19: 0.8 | E19: B- | G19: next 35% C, next 15% D, last 5% F.
D20: 0.83 | E20: B
A21: Performance index | D21: 0.87 | E21: B+
A22: Weight of overall grade | B22: 0.7 | D22: 0.9 | E22: A-
A23: Weight of submission rate | B23: 0.3 | D23: 0.93 | E23: A
D24: Lowest to highest.
A26: At-risk flags
A27: Overall grade below | B27: 0.7
A28: Submission rate below | B28: 0.8
A29: 'Watch' = within 10 points of either line.

Sheet Roster
A1: Roster
A2: One row per student. Names flow into every other tab.
A5: # | B5: Student | C5: Student ID | D5: Notes
A6: 1 | B6: Ava Johnson | C6: S1001
A7: 2 | B7: Liam Smith | C7: S1002
A8: 3 | B8: Mia Garcia | C8: S1003
A9: 4 | B9: Noah Brown | C9: S1004
A10: 5 | B10: Emma Davis | C10: S1005
A11: 6 | B11: Lucas Miller | C11: S1006
A12: 7 | B12: Sofia Wilson | C12: S1007
A13: 8 | B13: Ethan Moore | C13: S1008
A14: 9 | B14: Isabella Taylor | C14: S1009
A15: 10 | B15: Mason Anderson | C15: S1010
A16: 11 | B16: Chloe Thomas | C16: S1011
A17: 12 | B17: Logan Martinez | C17: S1012
... A29: 24 | B29: Owen Baker | C29: S1024
A30: 25
A31: 26
A32: 27
A33: 28
A34: 29
A35: 30
A36: 31
A37: 32
A38: 33
A39: 34
A40: 35
A41: 36
... A45: 40

Sheet Pacing
A1: Pacing Plan
A2: Units by week. Assignments take their due date from the end of their unit.
A3: This week: | C3: =IF(Setup!B8="","",INT((Setup!B8-Setup!B6)/7)+1)
H4: 1 | I4: 2 | J4: 3 | K4: 4 | L4: 5 | M4: 6 | N4: 7 | O4: 8 | P4: 9 | Q4: 10 | R4: 11 | S4: 12 | T4: 13 | U4: 14 | V4: 15 | W4: 16 | X4: 17 | Y4: 18 | Z4: 19 | AA4: 20
A5: # | B5: Unit | C5: Start wk | D5: Weeks | E5: Starts | F5: Ends | G5: Items | H5: =Setup!$B$6+(H$4-1)*7 | I5: =Setup!$B$6+(I$4-1)*7 | J5: =Setup!$B$6+(J$4-1)*7 | K5: =Setup!$B$6+(K$4-1)*7 | L5: =Setup!$B$6+(L$4-1)*7 | M5: =Setup!$B$6+(M$4-1)*7 | N5: =Setup!$B$6+(N$4-1)*7 | O5: =Setup!$B$6+(O$4-1)*7 | ... AA5: =Setup!$B$6+(AA$4-1)*7
A6: 1 | B6: Foundations | C6: 1 | D6: 3 | E6: =IF(OR(B6="",C6=""),"",Setup!$B$6+(C6-1)*7) | F6: =IF(OR(B6="",C6=""),"",Setup!$B$6+(C6+MAX(1,D6)-2)*7+4) | G6: =IF(B6="","",COUNTIF(Assignments!$C$6:$C$65,B6))
A7: 2 | B7: Linear Equations | C7: 4 | D7: 3 | E7: =IF(OR(B7="",C7=""),"",Setup!$B$6+(C7-1)*7) | F7: =IF(OR(B7="",C7=""),"",Setup!$B$6+(C7+MAX(1,D7)-2)*7+4) | G7: =IF(B7="","",COUNTIF(Assignments!$C$6:$C$65,B7))
A8: 3 | B8: Functions | C8: 7 | D8: 3 | E8: =IF(OR(B8="",C8=""),"",Setup!$B$6+(C8-1)*7) | F8: =IF(OR(B8="",C8=""),"",Setup!$B$6+(C8+MAX(1,D8)-2)*7+4) | G8: =IF(B8="","",COUNTIF(Assignments!$C$6:$C$65,B8))
A9: 4 | B9: Midterm Review | C9: 10 | D9: 1 | E9: =IF(OR(B9="",C9=""),"",Setup!$B$6+(C9-1)*7) | F9: =IF(OR(B9="",C9=""),"",Setup!$B$6+(C9+MAX(1,D9)-2)*7+4) | G9: =IF(B9="","",COUNTIF(Assignments!$C$6:$C$65,B9))
A10: 5 | B10: Systems of Equations | C10: 11 | D10: 3 | E10: =IF(OR(B10="",C10=""),"",Setup!$B$6+(C10-1)*7) | F10: =IF(OR(B10="",C10=""),"",Setup!$B$6+(C10+MAX(1,D10)-2)*7+4) | G10: =IF(B10="","",COUNTIF(Assignments!$C$6:$C$65,B10))
A11: 6 | B11: Quadratics | C11: 14 | D11: 3 | E11: =IF(OR(B11="",C11=""),"",Setup!$B$6+(C11-1)*7) | F11: =IF(OR(B11="",C11=""),"",Setup!$B$6+(C11+MAX(1,D11)-2)*7+4) | G11: =IF(B11="","",COUNTIF(Assignments!$C$6:$C$65,B11))
A12: 7 | B12: Final Review | C12: 17 | D12: 2 | E12: =IF(OR(B12="",C12=""),"",Setup!$B$6+(C12-1)*7) | F12: =IF(OR(B12="",C12=""),"",Setup!$B$6+(C12+MAX(1,D12)-2)*7+4) | G12: =IF(B12="","",COUNTIF(Assignments!$C$6:$C$65,B12))
A13: 8 | E13: =IF(OR(B13="",C13=""),"",Setup!$B$6+(C13-1)*7) | F13: =IF(OR(B13="",C13=""),"",Setup!$B$6+(C13+MAX(1,D13)-2)*7+4) | G13: =IF(B13="","",COUNTIF(Assignments!$C$6:$C$65,B13))
A14: 9 | E14: =IF(OR(B14="",C14=""),"",Setup!$B$6+(C14-1)*7) | F14: =IF(OR(B14="",C14=""),"",Setup!$B$6+(C14+MAX(1,D14)-2)*7+4) | G14: =IF(B14="","",COUNTIF(Assignments!$C$6:$C$65,B14))
A15: 10 | E15: =IF(OR(B15="",C15=""),"",Setup!$B$6+(C15-1)*7) | F15: =IF(OR(B15="",C15=""),"",Setup!$B$6+(C15+MAX(1,D15)-2)*7+4) | G15: =IF(B15="","",COUNTIF(Assignments!$C$6:$C$65,B15))
A16: 11 | E16: =IF(OR(B16="",C16=""),"",Setup!$B$6+(C16-1)*7) | F16: =IF(OR(B16="",C16=""),"",Setup!$B$6+(C16+MAX(1,D16)-2)*7+4) | G16: =IF(B16="","",COUNTIF(Assignments!$C$6:$C$65,B16))
A17: 12 | E17: =IF(OR(B17="",C17=""),"",Setup!$B$6+(C17-1)*7) | F17: =IF(OR(B17="",C17=""),"",Setup!$B$6+(C17+MAX(1,D17)-2)*7+4) | G17: =IF(B17="","",COUNTIF(Assignments!$C$6:$C$65,B17))
A18: 13 | E18: =IF(OR(B18="",C18=""),"",Setup!$B$6+(C18-1)*7) | F18: =IF(OR(B18="",C18=""),"",Setup!$B$6+(C18+MAX(1,D18)-2)*7+4) | G18: =IF(B18="","",COUNTIF(Assignments!$C$6:$C$65,B18))
A19: 14 | E19: =IF(OR(B19="",C19=""),"",Setup!$B$6+(C19-1)*7) | F19: =IF(OR(B19="",C19=""),"",Setup!$B$6+(C19+MAX(1,D19)-2)*7+4) | G19: =IF(B19="","",COUNTIF(Assignments!$C$6:$C$65,B19))
A20: 15 | E20: =IF(OR(B20="",C20=""),"",Setup!$B$6+(C20-1)*7) | F20: =IF(OR(B20="",C20=""),"",Setup!$B$6+(C20+MAX(1,D20)-2)*7+4) | G20: =IF(B20="","",COUNTIF(Assignments!$C$6:$C$65,B20))
A21: 16 | E21: =IF(OR(B21="",C21=""),"",Setup!$B$6+(C21-1)*7) | F21: =IF(OR(B21="",C21=""),"",Setup!$B$6+(C21+MAX(1,D21)-2)*7+4) | G21: =IF(B21="","",COUNTIF(Assignments!$C$6:$C$65,B21))
A22: 17 | E22: =IF(OR(B22="",C22=""),"",Setup!$B$6+(C22-1)*7) | F22: =IF(OR(B22="",C22=""),"",Setup!$B$6+(C22+MAX(1,D22)-2)*7+4) | G22: =IF(B22="","",COUNTIF(Assignments!$C$6:$C$65,B22))
A23: 18 | E23: =IF(OR(B23="",C23=""),"",Setup!$B$6+(C23-1)*7) | F23: =IF(OR(B23="",C23=""),"",Setup!$B$6+(C23+MAX(1,D23)-2)*7+4) | G23: =IF(B23="","",COUNTIF(Assignments!$C$6:$C$65,B23))
A24: 19 | E24: =IF(OR(B24="",C24=""),"",Setup!$B$6+(C24-1)*7) | F24: =IF(OR(B24="",C24=""),"",Setup!$B$6+(C24+MAX(1,D24)-2)*7+4) | G24: =IF(B24="","",COUNTIF(Assignments!$C$6:$C$65,B24))
A25: 20 | E25: =IF(OR(B25="",C25=""),"",Setup!$B$6+(C25-1)*7) | F25: =IF(OR(B25="",C25=""),"",Setup!$B$6+(C25+MAX(1,D25)-2)*7+4) | G25: =IF(B25="","",COUNTIF(Assignments!$C$6:$C$65,B25))
B27: Assignments due | H27: =COUNTIF(Assignments!$H$6:$H$65,H$4) | I27: =COUNTIF(Assignments!$H$6:$H$65,I$4) | J27: =COUNTIF(Assignments!$H$6:$H$65,J$4) | K27: =COUNTIF(Assignments!$H$6:$H$65,K$4) | L27: =COUNTIF(Assignments!$H$6:$H$65,L$4) | M27: =COUNTIF(Assignments!$H$6:$H$65,M$4) | N27: =COUNTIF(Assignments!$H$6:$H$65,N$4) | O27: =COUNTIF(Assignments!$H$6:$H$65,O$4) | ... AA27: =COUNTIF(Assignments!$H$6:$H$65,AA$4)
B28: Points due | H28: =SUMIF(Assignments!$H$6:$H$65,H$4,Assignments!$E$6:$E$65) | I28: =SUMIF(Assignments!$H$6:$H$65,I$4,Assignments!$E$6:$E$65) | J28: =SUMIF(Assignments!$H$6:$H$65,J$4,Assignments!$E$6:$E$65) | K28: =SUMIF(Assignments!$H$6:$H$65,K$4,Assignments!$E$6:$E$65) | L28: =SUMIF(Assignments!$H$6:$H$65,L$4,Assignments!$E$6:$E$65) | M28: =SUMIF(Assignments!$H$6:$H$65,M$4,Assignments!$E$6:$E$65) | N28: =SUMIF(Assignments!$H$6:$H$65,N$4,Assignments!$E$6:$E$65) | O28: =SUMIF(Assignments!$H$6:$H$65,O$4,Assignments!$E$6:$E$65) | ... AA28: =SUMIF(Assignments!$H$6:$H$65,AA$4,Assignments!$E$6:$E$65)

Sheet Assignments
A1: Assignments
A2: Pick a unit and the due date fills in. Type a date only if it differs from the end of the unit.
J3: Flag below: | K3: =Setup!B28
A5: # | B5: Assignment | C5: Unit | D5: Category | E5: Points | F5: Due date (optional) | G5: Due | H5: Week | I5: Due? | J5: Class avg | K5: Turned in | L5: Missing
A6: 1 | B6: Foundations: HW A | C6: Foundations | D6: Homework | E6: 10 | F6: 46254 | G6: =IF(B6="","",IF(F6<>"",F6,IFERROR(INDEX(Pacing!$F$6:$F$25,MATCH(C6,Pacing!$B$6:$B$25,0)),""))) | H6: =IF(G6="","",INT((G6-Setup!$B$6)/7)+1) | I6: =IF(AND(B6<>"",G6<>""),IF(G6<=Setup!$B$8,1,0),0) | J6: =IF(OR(B6="",N(E6)=0),"",IFERROR(AVERAGE(Gradebook!M$10:M$49)/E6,"")) | K6: =IF(I6<>1,"",IFERROR(COUNT(Gradebook!M$10:M$49)/(SUMPRODUCT(--(Gradebook!$B$10:$B$49<>""))-COUNTIF(Gradebook!M$10:M$49,"EX")),"")) | L6: =IF(B6="","",IF(I6=1,SUMPRODUCT((Gradebook!$B$10:$B$49<>"")*(Gradebook!M$10:M$49="")),0)+COUNTIF(Gradebook!M$10:M$49,"M"))
A7: 2 | B7: Foundations: HW B | C7: Foundations | D7: Homework | E7: 10 | F7: 46261 | G7: =IF(B7="","",IF(F7<>"",F7,IFERROR(INDEX(Pacing!$F$6:$F$25,MATCH(C7,Pacing!$B$6:$B$25,0)),""))) | H7: =IF(G7="","",INT((G7-Setup!$B$6)/7)+1) | I7: =IF(AND(B7<>"",G7<>""),IF(G7<=Setup!$B$8,1,0),0) | J7: =IF(OR(B7="",N(E7)=0),"",IFERROR(AVERAGE(Gradebook!N$10:N$49)/E7,"")) | K7: =IF(I7<>1,"",IFERROR(COUNT(Gradebook!N$10:N$49)/(SUMPRODUCT(--(Gradebook!$B$10:$B$49<>""))-COUNTIF(Gradebook!N$10:N$49,"EX")),"")) | L7: =IF(B7="","",IF(I7=1,SUMPRODUCT((Gradebook!$B$10:$B$49<>"")*(Gradebook!N$10:N$49="")),0)+COUNTIF(Gradebook!N$10:N$49,"M"))
A8: 3 | B8: Foundations: Quiz | C8: Foundations | D8: Quizzes | E8: 25 | F8: 46262 | G8: =IF(B8="","",IF(F8<>"",F8,IFERROR(INDEX(Pacing!$F$6:$F$25,MATCH(C8,Pacing!$B$6:$B$25,0)),""))) | H8: =IF(G8="","",INT((G8-Setup!$B$6)/7)+1) | I8: =IF(AND(B8<>"",G8<>""),IF(G8<=Setup!$B$8,1,0),0) | J8: =IF(OR(B8="",N(E8)=0),"",IFERROR(AVERAGE(Gradebook!O$10:O$49)/E8,"")) | K8: =IF(I8<>1,"",IFERROR(COUNT(Gradebook!O$10:O$49)/(SUMPRODUCT(--(Gradebook!$B$10:$B$49<>""))-COUNTIF(Gradebook!O$10:O$49,"EX")),"")) | L8: =IF(B8="","",IF(I8=1,SUMPRODUCT((Gradebook!$B$10:$B$49<>"")*(Gradebook!O$10:O$49="")),0)+COUNTIF(Gradebook!O$10:O$49,"M"))
A9: 4 | B9: Foundations: Participation | C9: Foundations | D9: Participation | E9: 10 | G9: =IF(B9="","",IF(F9<>"",F9,IFERROR(INDEX(Pacing!$F$6:$F$25,MATCH(C9,Pacing!$B$6:$B$25,0)),""))) | H9: =IF(G9="","",INT((G9-Setup!$B$6)/7)+1) | I9: =IF(AND(B9<>"",G9<>""),IF(G9<=Setup!$B$8,1,0),0) | J9: =IF(OR(B9="",N(E9)=0),"",IFERROR(AVERAGE(Gradebook!P$10:P$49)/E9,"")) | K9: =IF(I9<>1,"",IFERROR(COUNT(Gradebook!P$10:P$49)/(SUMPRODUCT(--(Gradebook!$B$10:$B$49<>""))-COUNTIF(Gradebook!P$10:P$49,"EX")),"")) | L9: =IF(B9="","",IF(I9=1,SUMPRODUCT((Gradebook!$B$10:$B$49<>"")*(Gradebook!P$10:P$49="")),0)+COUNTIF(Gradebook!P$10:P$49,"M"))
A10: 5 | B10: Foundations: Test | C10: Foundations | D10: Tests | E10: 100 | G10: =IF(B10="","",IF(F10<>"",F10,IFERROR(INDEX(Pacing!$F$6:$F$25,MATCH(C10,Pacing!$B$6:$B$25,0)),""))) | H10: =IF(G10="","",INT((G10-Setup!$B$6)/7)+1) | I10: =IF(AND(B10<>"",G10<>""),IF(G10<=Setup!$B$8,1,0),0) | J10: =IF(OR(B10="",N(E10)=0),"",IFERROR(AVERAGE(Gradebook!Q$10:Q$49)/E10,"")) | K10: =IF(I10<>1,"",IFERROR(COUNT(Gradebook!Q$10:Q$49)/(SUMPRODUCT(--(Gradebook!$B$10:$B$49<>""))-COUNTIF(Gradebook!Q$10:Q$49,"EX")),"")) | L10: =IF(B10="","",IF(I10=1,SUMPRODUCT((Gradebook!$B$10:$B$49<>"")*(Gradebook!Q$10:Q$49="")),0)+COUNTIF(Gradebook!Q$10:Q$49,"M"))
A11: 6 | B11: Linear Equations: HW A | C11: Linear Equations | D11: Homework | E11: 10 | F11: 46275 | G11: =IF(B11="","",IF(F11<>"",F11,IFERROR(INDEX(Pacing!$F$6:$F$25,MATCH(C11,Pacing!$B$6:$B$25,0)),""))) | H11: =IF(G11="","",INT((G11-Setup!$B$6)/7)+1) | I11: =IF(AND(B11<>"",G11<>""),IF(G11<=Setup!$B$8,1,0),0) | J11: =IF(OR(B11="",N(E11)=0),"",IFERROR(AVERAGE(Gradebook!R$10:R$49)/E11,"")) | K11: =IF(I11<>1,"",IFERROR(COUNT(Gradebook!R$10:R$49)/(SUMPRODUCT(--(Gradebook!$B$10:$B$49<>""))-COUNTIF(Gradebook!R$10:R$49,"EX")),"")) | L11: =IF(B11="","",IF(I11=1,SUMPRODUCT((Gradebook!$B$10:$B$49<>"")*(Gradebook!R$10:R$49="")),0)+COUNTIF(Gradebook!R$10:R$49,"M"))
A12: 7 | B12: Linear Equations: HW B | C12: Linear Equations | D12: Homework | E12: 10 | F12: 46282 | G12: =IF(B12="","",IF(F12<>"",F12,IFERROR(INDEX(Pacing!$F$6:$F$25,MATCH(C12,Pacing!$B$6:$B$25,0)),""))) | H12: =IF(G12="","",INT((G12-Setup!$B$6)/7)+1) | I12: =IF(AND(B12<>"",G12<>""),IF(G12<=Setup!$B$8,1,0),0) | J12: =IF(OR(B12="",N(E12)=0),"",IFERROR(AVERAGE(Gradebook!S$10:S$49)/E12,"")) | K12: =IF(I12<>1,"",IFERROR(COUNT(Gradebook!S$10:S$49)/(SUMPRODUCT(--(Gradebook!$B$10:$B$49<>""))-COUNTIF(Gradebook!S$10:S$49,"EX")),"")) | L12: =IF(B12="","",IF(I12=1,SUMPRODUCT((Gradebook!$B$10:$B$49<>"")*(Gradebook!S$10:S$49="")),0)+COUNTIF(Gradebook!S$10:S$49,"M"))
A13: 8 | B13: Linear Equations: Quiz | C13: Linear Equations | D13: Quizzes | E13: 25 | F13: 46283 | G13: =IF(B13="","",IF(F13<>"",F13,IFERROR(INDEX(Pacing!$F$6:$F$25,MATCH(C13,Pacing!$B$6:$B$25,0)),""))) | H13: =IF(G13="","",INT((G13-Setup!$B$6)/7)+1) | I13: =IF(AND(B13<>"",G13<>""),IF(G13<=Setup!$B$8,1,0),0) | J13: =IF(OR(B13="",N(E13)=0),"",IFERROR(AVERAGE(Gradebook!T$10:T$49)/E13,"")) | K13: =IF(I13<>1,"",IFERROR(COUNT(Gradebook!T$10:T$49)/(SUMPRODUCT(--(Gradebook!$B$10:$B$49<>""))-COUNTIF(Gradebook!T$10:T$49,"EX")),"")) | L13: =IF(B13="","",IF(I13=1,SUMPRODUCT((Gradebook!$B$10:$B$49<>"")*(Gradebook!T$10:T$49="")),0)+COUNTIF(Gradebook!T$10:T$49,"M"))
A14: 9 | B14: Linear Equations: Participation | C14: Linear Equations | D14: Participation | E14: 10 | G14: =IF(B14="","",IF(F14<>"",F14,IFERROR(INDEX(Pacing!$F$6:$F$25,MATCH(C14,Pacing!$B$6:$B$25,0)),""))) | H14: =IF(G14="","",INT((G14-Setup!$B$6)/7)+1) | I14: =IF(AND(B14<>"",G14<>""),IF(G14<=Setup!$B$8,1,0),0) | J14: =IF(OR(B14="",N(E14)=0),"",IFERROR(AVERAGE(Gradebook!U$10:U$49)/E14,"")) | K14: =IF(I14<>1,"",IFERROR(COUNT(Gradebook!U$10:U$49)/(SUMPRODUCT(--(Gradebook!$B$10:$B$49<>""))-COUNTIF(Gradebook!U$10:U$49,"EX")),"")) | L14: =IF(B14="","",IF(I14=1,SUMPRODUCT((Gradebook!$B$10:$B$49<>"")*(Gradebook!U$10:U$49="")),0)+COUNTIF(Gradebook!U$10:U$49,"M"))
A15: 10 | B15: Linear Equations: Test | C15: Linear Equations | D15: Tests | E15: 100 | G15: =IF(B15="","",IF(F15<>"",F15,IFERROR(INDEX(Pacing!$F$6:$F$25,MATCH(C15,Pacing!$B$6:$B$25,0)),""))) | H15: =IF(G15="","",INT((G15-Setup!$B$6)/7)+1) | I15: =IF(AND(B15<>"",G15<>""),IF(G15<=Setup!$B$8,1,0),0) | J15: =IF(OR(B15="",N(E15)=0),"",IFERROR(AVERAGE(Gradebook!V$10:V$49)/E15,"")) | K15: =IF(I15<>1,"",IFERROR(COUNT(Gradebook!V$10:V$49)/(SUMPRODUCT(--(Gradebook!$B$10:$B$49<>""))-COUNTIF(Gradebook!V$10:V$49,"EX")),"")) | L15: =IF(B15="","",IF(I15=1,SUMPRODUCT((Gradebook!$B$10:$B$49<>"")*(Gradebook!V$10:V$49="")),0)+COUNTIF(Gradebook!V$10:V$49,"M"))
A16: 11 | B16: Functions: HW A | C16: Functions | D16: Homework | E16: 10 | F16: 46296 | G16: =IF(B16="","",IF(F16<>"",F16,IFERROR(INDEX(Pacing!$F$6:$F$25,MATCH(C16,Pacing!$B$6:$B$25,0)),""))) | H16: =IF(G16="","",INT((G16-Setup!$B$6)/7)+1) | I16: =IF(AND(B16<>"",G16<>""),IF(G16<=Setup!$B$8,1,0),0) | J16: =IF(OR(B16="",N(E16)=0),"",IFERROR(AVERAGE(Gradebook!W$10:W$49)/E16,"")) | K16: =IF(I16<>1,"",IFERROR(COUNT(Gradebook!W$10:W$49)/(SUMPRODUCT(--(Gradebook!$B$10:$B$49<>""))-COUNTIF(Gradebook!W$10:W$49,"EX")),"")) | L16: =IF(B16="","",IF(I16=1,SUMPRODUCT((Gradebook!$B$10:$B$49<>"")*(Gradebook!W$10:W$49="")),0)+COUNTIF(Gradebook!W$10:W$49,"M"))
A17: 12 | B17: Functions: HW B | C17: Functions | D17: Homework | E17: 10 | F17: 46303 | G17: =IF(B17="","",IF(F17<>"",F17,IFERROR(INDEX(Pacing!$F$6:$F$25,MATCH(C17,Pacing!$B$6:$B$25,0)),""))) | H17: =IF(G17="","",INT((G17-Setup!$B$6)/7)+1) | I17: =IF(AND(B17<>"",G17<>""),IF(G17<=Setup!$B$8,1,0),0) | J17: =IF(OR(B17="",N(E17)=0),"",IFERROR(AVERAGE(Gradebook!X$10:X$49)/E17,"")) | K17: =IF(I17<>1,"",IFERROR(COUNT(Gradebook!X$10:X$49)/(SUMPRODUCT(--(Gradebook!$B$10:$B$49<>""))-COUNTIF(Gradebook!X$10:X$49,"EX")),"")) | L17: =IF(B17="","",IF(I17=1,SUMPRODUCT((Gradebook!$B$10:$B$49<>"")*(Gradebook!X$10:X$49="")),0)+COUNTIF(Gradebook!X$10:X$49,"M"))
A18: 13 | B18: Functions: Quiz | C18: Functions | D18: Quizzes | E18: 25 | F18: 46304 | G18: =IF(B18="","",IF(F18<>"",F18,IFERROR(INDEX(Pacing!$F$6:$F$25,MATCH(C18,Pacing!$B$6:$B$25,0)),""))) | H18: =IF(G18="","",INT((G18-Setup!$B$6)/7)+1) | I18: =IF(AND(B18<>"",G18<>""),IF(G18<=Setup!$B$8,1,0),0) | J18: =IF(OR(B18="",N(E18)=0),"",IFERROR(AVERAGE(Gradebook!Y$10:Y$49)/E18,"")) | K18: =IF(I18<>1,"",IFERROR(COUNT(Gradebook!Y$10:Y$49)/(SUMPRODUCT(--(Gradebook!$B$10:$B$49<>""))-COUNTIF(Gradebook!Y$10:Y$49,"EX")),"")) | L18: =IF(B18="","",IF(I18=1,SUMPRODUCT((Gradebook!$B$10:$B$49<>"")*(Gradebook!Y$10:Y$49="")),0)+COUNTIF(Gradebook!Y$10:Y$49,"M"))
A19: 14 | B19: Functions Project | C19: Functions | D19: Projects | E19: 50 | G19: =IF(B19="","",IF(F19<>"",F19,IFERROR(INDEX(Pacing!$F$6:$F$25,MATCH(C19,Pacing!$B$6:$B$25,0)),""))) | H19: =IF(G19="","",INT((G19-Setup!$B$6)/7)+1) | I19: =IF(AND(B19<>"",G19<>""),IF(G19<=Setup!$B$8,1,0),0) | J19: =IF(OR(B19="",N(E19)=0),"",IFERROR(AVERAGE(Gradebook!Z$10:Z$49)/E19,"")) | K19: =IF(I19<>1,"",IFERROR(COUNT(Gradebook!Z$10:Z$49)/(SUMPRODUCT(--(Gradebook!$B$10:$B$49<>""))-COUNTIF(Gradebook!Z$10:Z$49,"EX")),"")) | L19: =IF(B19="","",IF(I19=1,SUMPRODUCT((Gradebook!$B$10:$B$49<>"")*(Gradebook!Z$10:Z$49="")),0)+COUNTIF(Gradebook!Z$10:Z$49,"M"))
A20: 15 | B20: Functions: Participation | C20: Functions | D20: Participation | E20: 10 | G20: =IF(B20="","",IF(F20<>"",F20,IFERROR(INDEX(Pacing!$F$6:$F$25,MATCH(C20,Pacing!$B$6:$B$25,0)),""))) | H20: =IF(G20="","",INT((G20-Setup!$B$6)/7)+1) | I20: =IF(AND(B20<>"",G20<>""),IF(G20<=Setup!$B$8,1,0),0) | J20: =IF(OR(B20="",N(E20)=0),"",IFERROR(AVERAGE(Gradebook!AA$10:AA$49)/E20,"")) | K20: =IF(I20<>1,"",IFERROR(COUNT(Gradebook!AA$10:AA$49)/(SUMPRODUCT(--(Gradebook!$B$10:$B$49<>""))-COUNTIF(Gradebook!AA$10:AA$49,"EX")),"")) | L20: =IF(B20="","",IF(I20=1,SUMPRODUCT((Gradebook!$B$10:$B$49<>"")*(Gradebook!AA$10:AA$49="")),0)+COUNTIF(Gradebook!AA$10:AA$49,"M"))
A21: 16 | B21: Functions: Test | C21: Functions | D21: Tests | E21: 100 | G21: =IF(B21="","",IF(F21<>"",F21,IFERROR(INDEX(Pacing!$F$6:$F$25,MATCH(C21,Pacing!$B$6:$B$25,0)),""))) | H21: =IF(G21="","",INT((G21-Setup!$B$6)/7)+1) | I21: =IF(AND(B21<>"",G21<>""),IF(G21<=Setup!$B$8,1,0),0) | J21: =IF(OR(B21="",N(E21)=0),"",IFERROR(AVERAGE(Gradebook!AB$10:AB$49)/E21,"")) | K21: =IF(I21<>1,"",IFERROR(COUNT(Gradebook!AB$10:AB$49)/(SUMPRODUCT(--(Gradebook!$B$10:$B$49<>""))-COUNTIF(Gradebook!AB$10:AB$49,"EX")),"")) | L21: =IF(B21="","",IF(I21=1,SUMPRODUCT((Gradebook!$B$10:$B$49<>"")*(Gradebook!AB$10:AB$49="")),0)+COUNTIF(Gradebook!AB$10:AB$49,"M"))
A22: 17 | B22: Midterm Review Packet | C22: Midterm Review | D22: Homework | E22: 20 | G22: =IF(B22="","",IF(F22<>"",F22,IFERROR(INDEX(Pacing!$F$6:$F$25,MATCH(C22,Pacing!$B$6:$B$25,0)),""))) | H22: =IF(G22="","",INT((G22-Setup!$B$6)/7)+1) | I22: =IF(AND(B22<>"",G22<>""),IF(G22<=Setup!$B$8,1,0),0) | J22: =IF(OR(B22="",N(E22)=0),"",IFERROR(AVERAGE(Gradebook!AC$10:AC$49)/E22,"")) | K22: =IF(I22<>1,"",IFERROR(COUNT(Gradebook!AC$10:AC$49)/(SUMPRODUCT(--(Gradebook!$B$10:$B$49<>""))-COUNTIF(Gradebook!AC$10:AC$49,"EX")),"")) | L22: =IF(B22="","",IF(I22=1,SUMPRODUCT((Gradebook!$B$10:$B$49<>"")*(Gradebook!AC$10:AC$49="")),0)+COUNTIF(Gradebook!AC$10:AC$49,"M"))
A23: 18 | B23: Midterm Exam | C23: Midterm Review | D23: Tests | E23: 100 | G23: =IF(B23="","",IF(F23<>"",F23,IFERROR(INDEX(Pacing!$F$6:$F$25,MATCH(C23,Pacing!$B$6:$B$25,0)),""))) | H23: =IF(G23="","",INT((G23-Setup!$B$6)/7)+1) | I23: =IF(AND(B23<>"",G23<>""),IF(G23<=Setup!$B$8,1,0),0) | J23: =IF(OR(B23="",N(E23)=0),"",IFERROR(AVERAGE(Gradebook!AD$10:AD$49)/E23,"")) | K23: =IF(I23<>1,"",IFERROR(COUNT(Gradebook!AD$10:AD$49)/(SUMPRODUCT(--(Gradebook!$B$10:$B$49<>""))-COUNTIF(Gradebook!AD$10:AD$49,"EX")),"")) | L23: =IF(B23="","",IF(I23=1,SUMPRODUCT((Gradebook!$B$10:$B$49<>"")*(Gradebook!AD$10:AD$49="")),0)+COUNTIF(Gradebook!AD$10:AD$49,"M"))
A24: 19 | B24: Systems of Equations: HW A | C24: Systems of Equations | D24: Homework | E24: 10 | F24: 46324 | G24: =IF(B24="","",IF(F24<>"",F24,IFERROR(INDEX(Pacing!$F$6:$F$25,MATCH(C24,Pacing!$B$6:$B$25,0)),""))) | H24: =IF(G24="","",INT((G24-Setup!$B$6)/7)+1) | I24: =IF(AND(B24<>"",G24<>""),IF(G24<=Setup!$B$8,1,0),0) | J24: =IF(OR(B24="",N(E24)=0),"",IFERROR(AVERAGE(Gradebook!AE$10:AE$49)/E24,"")) | K24: =IF(I24<>1,"",IFERROR(COUNT(Gradebook!AE$10:AE$49)/(SUMPRODUCT(--(Gradebook!$B$10:$B$49<>""))-COUNTIF(Gradebook!AE$10:AE$49,"EX")),"")) | L24: =IF(B24="","",IF(I24=1,SUMPRODUCT((Gradebook!$B$10:$B$49<>"")*(Gradebook!AE$10:AE$49="")),0)+COUNTIF(Gradebook!AE$10:AE$49,"M"))
A25: 20 | B25: Systems of Equations: HW B | C25: Systems of Equations | D25: Homework | E25: 10 | F25: 46331 | G25: =IF(B25="","",IF(F25<>"",F25,IFERROR(INDEX(Pacing!$F$6:$F$25,MATCH(C25,Pacing!$B$6:$B$25,0)),""))) | H25: =IF(G25="","",INT((G25-Setup!$B$6)/7)+1) | I25: =IF(AND(B25<>"",G25<>""),IF(G25<=Setup!$B$8,1,0),0) | J25: =IF(OR(B25="",N(E25)=0),"",IFERROR(AVERAGE(Gradebook!AF$10:AF$49)/E25,"")) | K25: =IF(I25<>1,"",IFERROR(COUNT(Gradebook!AF$10:AF$49)/(SUMPRODUCT(--(Gradebook!$B$10:$B$49<>""))-COUNTIF(Gradebook!AF$10:AF$49,"EX")),"")) | L25: =IF(B25="","",IF(I25=1,SUMPRODUCT((Gradebook!$B$10:$B$49<>"")*(Gradebook!AF$10:AF$49="")),0)+COUNTIF(Gradebook!AF$10:AF$49,"M"))
A26: 21 | B26: Systems of Equations: Quiz | C26: Systems of Equations | D26: Quizzes | E26: 25 | F26: 46332 | G26: =IF(B26="","",IF(F26<>"",F26,IFERROR(INDEX(Pacing!$F$6:$F$25,MATCH(C26,Pacing!$B$6:$B$25,0)),""))) | H26: =IF(G26="","",INT((G26-Setup!$B$6)/7)+1) | I26: =IF(AND(B26<>"",G26<>""),IF(G26<=Setup!$B$8,1,0),0) | J26: =IF(OR(B26="",N(E26)=0),"",IFERROR(AVERAGE(Gradebook!AG$10:AG$49)/E26,"")) | K26: =IF(I26<>1,"",IFERROR(COUNT(Gradebook!AG$10:AG$49)/(SUMPRODUCT(--(Gradebook!$B$10:$B$49<>""))-COUNTIF(Gradebook!AG$10:AG$49,"EX")),"")) | L26: =IF(B26="","",IF(I26=1,SUMPRODUCT((Gradebook!$B$10:$B$49<>"")*(Gradebook!AG$10:AG$49="")),0)+COUNTIF(Gradebook!AG$10:AG$49,"M"))
A27: 22 | B27: Systems of Equations: Participation | C27: Systems of Equations | D27: Participation | E27: 10 | G27: =IF(B27="","",IF(F27<>"",F27,IFERROR(INDEX(Pacing!$F$6:$F$25,MATCH(C27,Pacing!$B$6:$B$25,0)),""))) | H27: =IF(G27="","",INT((G27-Setup!$B$6)/7)+1) | I27: =IF(AND(B27<>"",G27<>""),IF(G27<=Setup!$B$8,1,0),0) | J27: =IF(OR(B27="",N(E27)=0),"",IFERROR(AVERAGE(Gradebook!AH$10:AH$49)/E27,"")) | K27: =IF(I27<>1,"",IFERROR(COUNT(Gradebook!AH$10:AH$49)/(SUMPRODUCT(--(Gradebook!$B$10:$B$49<>""))-COUNTIF(Gradebook!AH$10:AH$49,"EX")),"")) | L27: =IF(B27="","",IF(I27=1,SUMPRODUCT((Gradebook!$B$10:$B$49<>"")*(Gradebook!AH$10:AH$49="")),0)+COUNTIF(Gradebook!AH$10:AH$49,"M"))
A28: 23 | B28: Systems of Equations: Test | C28: Systems of Equations | D28: Tests | E28: 100 | G28: =IF(B28="","",IF(F28<>"",F28,IFERROR(INDEX(Pacing!$F$6:$F$25,MATCH(C28,Pacing!$B$6:$B$25,0)),""))) | H28: =IF(G28="","",INT((G28-Setup!$B$6)/7)+1) | I28: =IF(AND(B28<>"",G28<>""),IF(G28<=Setup!$B$8,1,0),0) | J28: =IF(OR(B28="",N(E28)=0),"",IFERROR(AVERAGE(Gradebook!AI$10:AI$49)/E28,"")) | K28: =IF(I28<>1,"",IFERROR(COUNT(Gradebook!AI$10:AI$49)/(SUMPRODUCT(--(Gradebook!$B$10:$B$49<>""))-COUNTIF(Gradebook!AI$10:AI$49,"EX")),"")) | L28: =IF(B28="","",IF(I28=1,SUMPRODUCT((Gradebook!$B$10:$B$49<>"")*(Gradebook!AI$10:AI$49="")),0)+COUNTIF(Gradebook!AI$10:AI$49,"M"))
A29: 24 | B29: Quadratics: HW A | C29: Quadratics | D29: Homework | E29: 10 | F29: 46345 | G29: =IF(B29="","",IF(F29<>"",F29,IFERROR(INDEX(Pacing!$F$6:$F$25,MATCH(C29,Pacing!$B$6:$B$25,0)),""))) | H29: =IF(G29="","",INT((G29-Setup!$B$6)/7)+1) | I29: =IF(AND(B29<>"",G29<>""),IF(G29<=Setup!$B$8,1,0),0) | J29: =IF(OR(B29="",N(E29)=0),"",IFERROR(AVERAGE(Gradebook!AJ$10:AJ$49)/E29,"")) | K29: =IF(I29<>1,"",IFERROR(COUNT(Gradebook!AJ$10:AJ$49)/(SUMPRODUCT(--(Gradebook!$B$10:$B$49<>""))-COUNTIF(Gradebook!AJ$10:AJ$49,"EX")),"")) | L29: =IF(B29="","",IF(I29=1,SUMPRODUCT((Gradebook!$B$10:$B$49<>"")*(Gradebook!AJ$10:AJ$49="")),0)+COUNTIF(Gradebook!AJ$10:AJ$49,"M"))
A30: 25 | B30: Quadratics: HW B | C30: Quadratics | D30: Homework | E30: 10 | F30: 46352 | G30: =IF(B30="","",IF(F30<>"",F30,IFERROR(INDEX(Pacing!$F$6:$F$25,MATCH(C30,Pacing!$B$6:$B$25,0)),""))) | H30: =IF(G30="","",INT((G30-Setup!$B$6)/7)+1) | I30: =IF(AND(B30<>"",G30<>""),IF(G30<=Setup!$B$8,1,0),0) | J30: =IF(OR(B30="",N(E30)=0),"",IFERROR(AVERAGE(Gradebook!AK$10:AK$49)/E30,"")) | K30: =IF(I30<>1,"",IFERROR(COUNT(Gradebook!AK$10:AK$49)/(SUMPRODUCT(--(Gradebook!$B$10:$B$49<>""))-COUNTIF(Gradebook!AK$10:AK$49,"EX")),"")) | L30: =IF(B30="","",IF(I30=1,SUMPRODUCT((Gradebook!$B$10:$B$49<>"")*(Gradebook!AK$10:AK$49="")),0)+COUNTIF(Gradebook!AK$10:AK$49,"M"))
A31: 26 | B31: Quadratics: Quiz | C31: Quadratics | D31: Quizzes | E31: 25 | F31: 46353 | G31: =IF(B31="","",IF(F31<>"",F31,IFERROR(INDEX(Pacing!$F$6:$F$25,MATCH(C31,Pacing!$B$6:$B$25,0)),""))) | H31: =IF(G31="","",INT((G31-Setup!$B$6)/7)+1) | I31: =IF(AND(B31<>"",G31<>""),IF(G31<=Setup!$B$8,1,0),0) | J31: =IF(OR(B31="",N(E31)=0),"",IFERROR(AVERAGE(Gradebook!AL$10:AL$49)/E31,"")) | K31: =IF(I31<>1,"",IFERROR(COUNT(Gradebook!AL$10:AL$49)/(SUMPRODUCT(--(Gradebook!$B$10:$B$49<>""))-COUNTIF(Gradebook!AL$10:AL$49,"EX")),"")) | L31: =IF(B31="","",IF(I31=1,SUMPRODUCT((Gradebook!$B$10:$B$49<>"")*(Gradebook!AL$10:AL$49="")),0)+COUNTIF(Gradebook!AL$10:AL$49,"M"))
A32: 27 | B32: Quadratics: Participation | C32: Quadratics | D32: Participation | E32: 10 | G32: =IF(B32="","",IF(F32<>"",F32,IFERROR(INDEX(Pacing!$F$6:$F$25,MATCH(C32,Pacing!$B$6:$B$25,0)),""))) | H32: =IF(G32="","",INT((G32-Setup!$B$6)/7)+1) | I32: =IF(AND(B32<>"",G32<>""),IF(G32<=Setup!$B$8,1,0),0) | J32: =IF(OR(B32="",N(E32)=0),"",IFERROR(AVERAGE(Gradebook!AM$10:AM$49)/E32,"")) | K32: =IF(I32<>1,"",IFERROR(COUNT(Gradebook!AM$10:AM$49)/(SUMPRODUCT(--(Gradebook!$B$10:$B$49<>""))-COUNTIF(Gradebook!AM$10:AM$49,"EX")),"")) | L32: =IF(B32="","",IF(I32=1,SUMPRODUCT((Gradebook!$B$10:$B$49<>"")*(Gradebook!AM$10:AM$49="")),0)+COUNTIF(Gradebook!AM$10:AM$49,"M"))
A33: 28 | B33: Quadratics: Test | C33: Quadratics | D33: Tests | E33: 100 | G33: =IF(B33="","",IF(F33<>"",F33,IFERROR(INDEX(Pacing!$F$6:$F$25,MATCH(C33,Pacing!$B$6:$B$25,0)),""))) | H33: =IF(G33="","",INT((G33-Setup!$B$6)/7)+1) | I33: =IF(AND(B33<>"",G33<>""),IF(G33<=Setup!$B$8,1,0),0) | J33: =IF(OR(B33="",N(E33)=0),"",IFERROR(AVERAGE(Gradebook!AN$10:AN$49)/E33,"")) | K33: =IF(I33<>1,"",IFERROR(COUNT(Gradebook!AN$10:AN$49)/(SUMPRODUCT(--(Gradebook!$B$10:$B$49<>""))-COUNTIF(Gradebook!AN$10:AN$49,"EX")),"")) | L33: =IF(B33="","",IF(I33=1,SUMPRODUCT((Gradebook!$B$10:$B$49<>"")*(Gradebook!AN$10:AN$49="")),0)+COUNTIF(Gradebook!AN$10:AN$49,"M"))
A34: 29 | B34: Final Review Packet | C34: Final Review | D34: Homework | E34: 20 | G34: =IF(B34="","",IF(F34<>"",F34,IFERROR(INDEX(Pacing!$F$6:$F$25,MATCH(C34,Pacing!$B$6:$B$25,0)),""))) | H34: =IF(G34="","",INT((G34-Setup!$B$6)/7)+1) | I34: =IF(AND(B34<>"",G34<>""),IF(G34<=Setup!$B$8,1,0),0) | J34: =IF(OR(B34="",N(E34)=0),"",IFERROR(AVERAGE(Gradebook!AO$10:AO$49)/E34,"")) | K34: =IF(I34<>1,"",IFERROR(COUNT(Gradebook!AO$10:AO$49)/(SUMPRODUCT(--(Gradebook!$B$10:$B$49<>""))-COUNTIF(Gradebook!AO$10:AO$49,"EX")),"")) | L34: =IF(B34="","",IF(I34=1,SUMPRODUCT((Gradebook!$B$10:$B$49<>"")*(Gradebook!AO$10:AO$49="")),0)+COUNTIF(Gradebook!AO$10:AO$49,"M"))
A35: 30 | B35: Final Exam | C35: Final Review | D35: Tests | E35: 100 | G35: =IF(B35="","",IF(F35<>"",F35,IFERROR(INDEX(Pacing!$F$6:$F$25,MATCH(C35,Pacing!$B$6:$B$25,0)),""))) | H35: =IF(G35="","",INT((G35-Setup!$B$6)/7)+1) | I35: =IF(AND(B35<>"",G35<>""),IF(G35<=Setup!$B$8,1,0),0) | J35: =IF(OR(B35="",N(E35)=0),"",IFERROR(AVERAGE(Gradebook!AP$10:AP$49)/E35,"")) | K35: =IF(I35<>1,"",IFERROR(COUNT(Gradebook!AP$10:AP$49)/(SUMPRODUCT(--(Gradebook!$B$10:$B$49<>""))-COUNTIF(Gradebook!AP$10:AP$49,"EX")),"")) | L35: =IF(B35="","",IF(I35=1,SUMPRODUCT((Gradebook!$B$10:$B$49<>"")*(Gradebook!AP$10:AP$49="")),0)+COUNTIF(Gradebook!AP$10:AP$49,"M"))
A36: 31 | G36: =IF(B36="","",IF(F36<>"",F36,IFERROR(INDEX(Pacing!$F$6:$F$25,MATCH(C36,Pacing!$B$6:$B$25,0)),""))) | H36: =IF(G36="","",INT((G36-Setup!$B$6)/7)+1) | I36: =IF(AND(B36<>"",G36<>""),IF(G36<=Setup!$B$8,1,0),0) | J36: =IF(OR(B36="",N(E36)=0),"",IFERROR(AVERAGE(Gradebook!AQ$10:AQ$49)/E36,"")) | K36: =IF(I36<>1,"",IFERROR(COUNT(Gradebook!AQ$10:AQ$49)/(SUMPRODUCT(--(Gradebook!$B$10:$B$49<>""))-COUNTIF(Gradebook!AQ$10:AQ$49,"EX")),"")) | L36: =IF(B36="","",IF(I36=1,SUMPRODUCT((Gradebook!$B$10:$B$49<>"")*(Gradebook!AQ$10:AQ$49="")),0)+COUNTIF(Gradebook!AQ$10:AQ$49,"M"))
A37: 32 | G37: =IF(B37="","",IF(F37<>"",F37,IFERROR(INDEX(Pacing!$F$6:$F$25,MATCH(C37,Pacing!$B$6:$B$25,0)),""))) | H37: =IF(G37="","",INT((G37-Setup!$B$6)/7)+1) | I37: =IF(AND(B37<>"",G37<>""),IF(G37<=Setup!$B$8,1,0),0) | J37: =IF(OR(B37="",N(E37)=0),"",IFERROR(AVERAGE(Gradebook!AR$10:AR$49)/E37,"")) | K37: =IF(I37<>1,"",IFERROR(COUNT(Gradebook!AR$10:AR$49)/(SUMPRODUCT(--(Gradebook!$B$10:$B$49<>""))-COUNTIF(Gradebook!AR$10:AR$49,"EX")),"")) | L37: =IF(B37="","",IF(I37=1,SUMPRODUCT((Gradebook!$B$10:$B$49<>"")*(Gradebook!AR$10:AR$49="")),0)+COUNTIF(Gradebook!AR$10:AR$49,"M"))
A38: 33 | G38: =IF(B38="","",IF(F38<>"",F38,IFERROR(INDEX(Pacing!$F$6:$F$25,MATCH(C38,Pacing!$B$6:$B$25,0)),""))) | H38: =IF(G38="","",INT((G38-Setup!$B$6)/7)+1) | I38: =IF(AND(B38<>"",G38<>""),IF(G38<=Setup!$B$8,1,0),0) | J38: =IF(OR(B38="",N(E38)=0),"",IFERROR(AVERAGE(Gradebook!AS$10:AS$49)/E38,"")) | K38: =IF(I38<>1,"",IFERROR(COUNT(Gradebook!AS$10:AS$49)/(SUMPRODUCT(--(Gradebook!$B$10:$B$49<>""))-COUNTIF(Gradebook!AS$10:AS$49,"EX")),"")) | L38: =IF(B38="","",IF(I38=1,SUMPRODUCT((Gradebook!$B$10:$B$49<>"")*(Gradebook!AS$10:AS$49="")),0)+COUNTIF(Gradebook!AS$10:AS$49,"M"))
A39: 34 | G39: =IF(B39="","",IF(F39<>"",F39,IFERROR(INDEX(Pacing!$F$6:$F$25,MATCH(C39,Pacing!$B$6:$B$25,0)),""))) | H39: =IF(G39="","",INT((G39-Setup!$B$6)/7)+1) | I39: =IF(AND(B39<>"",G39<>""),IF(G39<=Setup!$B$8,1,0),0) | J39: =IF(OR(B39="",N(E39)=0),"",IFERROR(AVERAGE(Gradebook!AT$10:AT$49)/E39,"")) | K39: =IF(I39<>1,"",IFERROR(COUNT(Gradebook!AT$10:AT$49)/(SUMPRODUCT(--(Gradebook!$B$10:$B$49<>""))-COUNTIF(Gradebook!AT$10:AT$49,"EX")),"")) | L39: =IF(B39="","",IF(I39=1,SUMPRODUCT((Gradebook!$B$10:$B$49<>"")*(Gradebook!AT$10:AT$49="")),0)+COUNTIF(Gradebook!AT$10:AT$49,"M"))
A40: 35 | G40: =IF(B40="","",IF(F40<>"",F40,IFERROR(INDEX(Pacing!$F$6:$F$25,MATCH(C40,Pacing!$B$6:$B$25,0)),""))) | H40: =IF(G40="","",INT((G40-Setup!$B$6)/7)+1) | I40: =IF(AND(B40<>"",G40<>""),IF(G40<=Setup!$B$8,1,0),0) | J40: =IF(OR(B40="",N(E40)=0),"",IFERROR(AVERAGE(Gradebook!AU$10:AU$49)/E40,"")) | K40: =IF(I40<>1,"",IFERROR(COUNT(Gradebook!AU$10:AU$49)/(SUMPRODUCT(--(Gradebook!$B$10:$B$49<>""))-COUNTIF(Gradebook!AU$10:AU$49,"EX")),"")) | L40: =IF(B40="","",IF(I40=1,SUMPRODUCT((Gradebook!$B$10:$B$49<>"")*(Gradebook!AU$10:AU$49="")),0)+COUNTIF(Gradebook!AU$10:AU$49,"M"))
A41: 36 | G41: =IF(B41="","",IF(F41<>"",F41,IFERROR(INDEX(Pacing!$F$6:$F$25,MATCH(C41,Pacing!$B$6:$B$25,0)),""))) | H41: =IF(G41="","",INT((G41-Setup!$B$6)/7)+1) | I41: =IF(AND(B41<>"",G41<>""),IF(G41<=Setup!$B$8,1,0),0) | J41: =IF(OR(B41="",N(E41)=0),"",IFERROR(AVERAGE(Gradebook!AV$10:AV$49)/E41,"")) | K41: =IF(I41<>1,"",IFERROR(COUNT(Gradebook!AV$10:AV$49)/(SUMPRODUCT(--(Gradebook!$B$10:$B$49<>""))-COUNTIF(Gradebook!AV$10:AV$49,"EX")),"")) | L41: =IF(B41="","",IF(I41=1,SUMPRODUCT((Gradebook!$B$10:$B$49<>"")*(Gradebook!AV$10:AV$49="")),0)+COUNTIF(Gradebook!AV$10:AV$49,"M"))
...

Sheet Gradebook
A1: ="Gradebook | "&Setup!B4
A2: Enter scores in the white grid. M = missing (0). EX = excused. Blank + past due = missing.
B3: At-risk lines: | C3: =Setup!B27 | E3: =Setup!B28 | G3: Weight | H3: =Setup!B12 | I3: =Setup!B13 | J3: =Setup!B14 | K3: =Setup!B15 | L3: =Setup!B16
M4: 1 | N4: 2 | O4: 3 | P4: 4 | Q4: 5 | R4: 6 | S4: 7 | T4: 8 | U4: 9 | V4: 10 | W4: 11 | X4: 12 | Y4: 13 | Z4: 14 | AA4: 15 | AB4: 16 | AC4: 17 | AD4: 18 | AE4: 19 | AF4: 20 | AG4: 21 | AH4: 22 | AI4: 23 | AJ4: 24 | AK4: 25 | AL4: 26 | AM4: 27 | AN4: 28 | AO4: 29 | AP4: 30 | AQ4: 31 | AR4: 32 | AS4: 33 | AT4: 34 | AU4: 35 | AV4: 36 | AW4: 37 | AX4: 38 | AY4: 39 | AZ4: 40 | BA4: 41 | BB4: 42 | BC4: 43 | BD4: 44 | BE4: 45 | BF4: 46 | BG4: 47 | BH4: 48 | BI4: 49 | BJ4: 50 | BK4: 51 | BL4: 52 | BM4: 53 | BN4: 54 | BO4: 55 | BP4: 56 | BQ4: 57 | BR4: 58 | BS4: 59 | BT4: 60
L5: Assignment > | M5: =IF(INDEX(Assignments!$B$6:$B$65,M$4)="","",INDEX(Assignments!$B$6:$B$65,M$4)) | N5: =IF(INDEX(Assignments!$B$6:$B$65,N$4)="","",INDEX(Assignments!$B$6:$B$65,N$4)) | O5: =IF(INDEX(Assignments!$B$6:$B$65,O$4)="","",INDEX(Assignments!$B$6:$B$65,O$4)) | P5: =IF(INDEX(Assignments!$B$6:$B$65,P$4)="","",INDEX(Assignments!$B$6:$B$65,P$4)) | Q5: =IF(INDEX(Assignments!$B$6:$B$65,Q$4)="","",INDEX(Assignments!$B$6:$B$65,Q$4)) | R5: =IF(INDEX(Assignments!$B$6:$B$65,R$4)="","",INDEX(Assignments!$B$6:$B$65,R$4)) | S5: =IF(INDEX(Assignments!$B$6:$B$65,S$4)="","",INDEX(Assignments!$B$6:$B$65,S$4)) | T5: =IF(INDEX(Assignments!$B$6:$B$65,T$4)="","",INDEX(Assignments!$B$6:$B$65,T$4)) | ... BT5: =IF(INDEX(Assignments!$B$6:$B$65,BT$4)="","",INDEX(Assignments!$B$6:$B$65,BT$4))
L6: Category > | M6: =IF(M$5="","",INDEX(Assignments!$D$6:$D$65,M$4)) | N6: =IF(N$5="","",INDEX(Assignments!$D$6:$D$65,N$4)) | O6: =IF(O$5="","",INDEX(Assignments!$D$6:$D$65,O$4)) | P6: =IF(P$5="","",INDEX(Assignments!$D$6:$D$65,P$4)) | Q6: =IF(Q$5="","",INDEX(Assignments!$D$6:$D$65,Q$4)) | R6: =IF(R$5="","",INDEX(Assignments!$D$6:$D$65,R$4)) | S6: =IF(S$5="","",INDEX(Assignments!$D$6:$D$65,S$4)) | T6: =IF(T$5="","",INDEX(Assignments!$D$6:$D$65,T$4)) | ... BT6: =IF(BT$5="","",INDEX(Assignments!$D$6:$D$65,BT$4))
L7: Points > | M7: =IF(M$5="",0,N(INDEX(Assignments!$E$6:$E$65,M$4))) | N7: =IF(N$5="",0,N(INDEX(Assignments!$E$6:$E$65,N$4))) | O7: =IF(O$5="",0,N(INDEX(Assignments!$E$6:$E$65,O$4))) | P7: =IF(P$5="",0,N(INDEX(Assignments!$E$6:$E$65,P$4))) | Q7: =IF(Q$5="",0,N(INDEX(Assignments!$E$6:$E$65,Q$4))) | R7: =IF(R$5="",0,N(INDEX(Assignments!$E$6:$E$65,R$4))) | S7: =IF(S$5="",0,N(INDEX(Assignments!$E$6:$E$65,S$4))) | T7: =IF(T$5="",0,N(INDEX(Assignments!$E$6:$E$65,T$4))) | ... BT7: =IF(BT$5="",0,N(INDEX(Assignments!$E$6:$E$65,BT$4)))
L8: Due > | M8: =INDEX(Assignments!$I$6:$I$65,M$4) | N8: =INDEX(Assignments!$I$6:$I$65,N$4) | O8: =INDEX(Assignments!$I$6:$I$65,O$4) | P8: =INDEX(Assignments!$I$6:$I$65,P$4) | Q8: =INDEX(Assignments!$I$6:$I$65,Q$4) | R8: =INDEX(Assignments!$I$6:$I$65,R$4) | S8: =INDEX(Assignments!$I$6:$I$65,S$4) | T8: =INDEX(Assignments!$I$6:$I$65,T$4) | ... BT8: =INDEX(Assignments!$I$6:$I$65,BT$4)
A9: # | B9: Student | C9: Overall | D9: Grade | E9: Turned in | F9: Missing | G9: Score % (turned in) | H9: =Setup!A12 | I9: =Setup!A13 | J9: =Setup!A14 | K9: =Setup!A15 | L9: =Setup!A16 | M9: Score | N9: Score | O9: Score | P9: Score | Q9: Score | R9: Score | S9: Score | T9: Score | U9: Score | V9: Score | W9: Score | X9: Score | Y9: Score | Z9: Score | AA9: Score | AB9: Score | AC9: Score | AD9: Score | AE9: Score | AF9: Score | AG9: Score | AH9: Score | AI9: Score | AJ9: Score | AK9: Score | AL9: Score | AM9: Score | AN9: Score | AO9: Score | AP9: Score | AQ9: Score | AR9: Score | AS9: Score | AT9: Score | AU9: Score | AV9: Score | AW9: Score | AX9: Score | AY9: Score | AZ9: Score | BA9: Score | BB9: Score | BC9: Score | BD9: Score | BE9: Score | BF9: Score | BG9: Score | BH9: Score | BI9: Score | BJ9: Score | BK9: Score | BL9: Score | BM9: Score | BN9: Score | BO9: Score | BP9: Score | BQ9: Score | BR9: Score | BS9: Score | BT9: Score
A10: 1 | B10: =IF(Roster!B6="","",Roster!B6) | C10: =IF($B10="","",IFERROR(SUMPRODUCT($H$3:$L$3,H10:L10)/SUMPRODUCT($H$3:$L$3,--ISNUMBER(H10:L10)),"")) | D10: =IF(C10="","",VLOOKUP(C10,Setup!$D$12:$E$23,2,TRUE)) | E10: =IF($B10="","",IFERROR(SUMPRODUCT($M$8:$BT$8*ISNUMBER($M10:$BT10))/SUMPRODUCT($M$8:$BT$8*($M10:$BT10<>"EX")),"")) | F10: =IF($B10="","",SUMPRODUCT($M$8:$BT$8*($M10:$BT10=""))+COUNTIF($M10:$BT10,"M")) | G10: =IF($B10="","",IFERROR(SUM($M10:$BT10)/SUMPRODUCT($M$7:$BT$7*ISNUMBER($M10:$BT10)),"")) | H10: =IF($B10="","",IFERROR(SUMIFS($M10:$BT10,$M$6:$BT$6,H$9)/SUMPRODUCT(($M$6:$BT$6=H$9)*$M$7:$BT$7*(ISNUMBER($M10:$BT10)+($M10:$BT10="M")+(Setup!$B$9="Yes")*$M$8:$BT$8*($M10:$BT10=""))),"")) | I10: =IF($B10="","",IFERROR(SUMIFS($M10:$BT10,$M$6:$BT$6,I$9)/SUMPRODUCT(($M$6:$BT$6=I$9)*$M$7:$BT$7*(ISNUMBER($M10:$BT10)+($M10:$BT10="M")+(Setup!$B$9="Yes")*$M$8:$BT$8*($M10:$BT10=""))),"")) | J10: =IF($B10="","",IFERROR(SUMIFS($M10:$BT10,$M$6:$BT$6,J$9)/SUMPRODUCT(($M$6:$BT$6=J$9)*$M$7:$BT$7*(ISNUMBER($M10:$BT10)+($M10:$BT10="M")+(Setup!$B$9="Yes")*$M$8:$BT$8*($M10:$BT10=""))),"")) | K10: =IF($B10="","",IFERROR(SUMIFS($M10:$BT10,$M$6:$BT$6,K$9)/SUMPRODUCT(($M$6:$BT$6=K$9)*$M$7:$BT$7*(ISNUMBER($M10:$BT10)+($M10:$BT10="M")+(Setup!$B$9="Yes")*$M$8:$BT$8*($M10:$BT10=""))),"")) | L10: =IF($B10="","",IFERROR(SUMIFS($M10:$BT10,$M$6:$BT$6,L$9)/SUMPRODUCT(($M$6:$BT$6=L$9)*$M$7:$BT$7*(ISNUMBER($M10:$BT10)+($M10:$BT10="M")+(Setup!$B$9="Yes")*$M$8:$BT$8*($M10:$BT10=""))),"")) | M10: 8.5 | N10: 7.7 | O10: 23 | P10: EX | Q10: 81 | R10: 8.4 | S10: 7.8 | T10: M | U10: 7 | V10: 75 | W10: 8.3 | X10: 8.4 | Y10: 18
A11: 2 | B11: =IF(Roster!B7="","",Roster!B7) | C11: =IF($B11="","",IFERROR(SUMPRODUCT($H$3:$L$3,H11:L11)/SUMPRODUCT($H$3:$L$3,--ISNUMBER(H11:L11)),"")) | D11: =IF(C11="","",VLOOKUP(C11,Setup!$D$12:$E$23,2,TRUE)) | E11: =IF($B11="","",IFERROR(SUMPRODUCT($M$8:$BT$8*ISNUMBER($M11:$BT11))/SUMPRODUCT($M$8:$BT$8*($M11:$BT11<>"EX")),"")) | F11: =IF($B11="","",SUMPRODUCT($M$8:$BT$8*($M11:$BT11=""))+COUNTIF($M11:$BT11,"M")) | G11: =IF($B11="","",IFERROR(SUM($M11:$BT11)/SUMPRODUCT($M$7:$BT$7*ISNUMBER($M11:$BT11)),"")) | H11: =IF($B11="","",IFERROR(SUMIFS($M11:$BT11,$M$6:$BT$6,H$9)/SUMPRODUCT(($M$6:$BT$6=H$9)*$M$7:$BT$7*(ISNUMBER($M11:$BT11)+($M11:$BT11="M")+(Setup!$B$9="Yes")*$M$8:$BT$8*($M11:$BT11=""))),"")) | I11: =IF($B11="","",IFERROR(SUMIFS($M11:$BT11,$M$6:$BT$6,I$9)/SUMPRODUCT(($M$6:$BT$6=I$9)*$M$7:$BT$7*(ISNUMBER($M11:$BT11)+($M11:$BT11="M")+(Setup!$B$9="Yes")*$M$8:$BT$8*($M11:$BT11=""))),"")) | J11: =IF($B11="","",IFERROR(SUMIFS($M11:$BT11,$M$6:$BT$6,J$9)/SUMPRODUCT(($M$6:$BT$6=J$9)*$M$7:$BT$7*(ISNUMBER($M11:$BT11)+($M11:$BT11="M")+(Setup!$B$9="Yes")*$M$8:$BT$8*($M11:$BT11=""))),"")) | K11: =IF($B11="","",IFERROR(SUMIFS($M11:$BT11,$M$6:$BT$6,K$9)/SUMPRODUCT(($M$6:$BT$6=K$9)*$M$7:$BT$7*(ISNUMBER($M11:$BT11)+($M11:$BT11="M")+(Setup!$B$9="Yes")*$M$8:$BT$8*($M11:$BT11=""))),"")) | L11: =IF($B11="","",IFERROR(SUMIFS($M11:$BT11,$M$6:$BT$6,L$9)/SUMPRODUCT(($M$6:$BT$6=L$9)*$M$7:$BT$7*(ISNUMBER($M11:$BT11)+($M11:$BT11="M")+(Setup!$B$9="Yes")*$M$8:$BT$8*($M11:$BT11=""))),"")) | M11: 6.9 | N11: 8.2 | O11: 19 | P11: 7 | Q11: 81 | R11: 8.7 | S11: 8 | T11: 18 | U11: 8.1 | V11: EX | W11: 7 | Y11: 18
A12: 3 | B12: =IF(Roster!B8="","",Roster!B8) | C12: =IF($B12="","",IFERROR(SUMPRODUCT($H$3:$L$3,H12:L12)/SUMPRODUCT($H$3:$L$3,--ISNUMBER(H12:L12)),"")) | D12: =IF(C12="","",VLOOKUP(C12,Setup!$D$12:$E$23,2,TRUE)) | E12: =IF($B12="","",IFERROR(SUMPRODUCT($M$8:$BT$8*ISNUMBER($M12:$BT12))/SUMPRODUCT($M$8:$BT$8*($M12:$BT12<>"EX")),"")) | F12: =IF($B12="","",SUMPRODUCT($M$8:$BT$8*($M12:$BT12=""))+COUNTIF($M12:$BT12,"M")) | G12: =IF($B12="","",IFERROR(SUM($M12:$BT12)/SUMPRODUCT($M$7:$BT$7*ISNUMBER($M12:$BT12)),"")) | H12: =IF($B12="","",IFERROR(SUMIFS($M12:$BT12,$M$6:$BT$6,H$9)/SUMPRODUCT(($M$6:$BT$6=H$9)*$M$7:$BT$7*(ISNUMBER($M12:$BT12)+($M12:$BT12="M")+(Setup!$B$9="Yes")*$M$8:$BT$8*($M12:$BT12=""))),"")) | I12: =IF($B12="","",IFERROR(SUMIFS($M12:$BT12,$M$6:$BT$6,I$9)/SUMPRODUCT(($M$6:$BT$6=I$9)*$M$7:$BT$7*(ISNUMBER($M12:$BT12)+($M12:$BT12="M")+(Setup!$B$9="Yes")*$M$8:$BT$8*($M12:$BT12=""))),"")) | J12: =IF($B12="","",IFERROR(SUMIFS($M12:$BT12,$M$6:$BT$6,J$9)/SUMPRODUCT(($M$6:$BT$6=J$9)*$M$7:$BT$7*(ISNUMBER($M12:$BT12)+($M12:$BT12="M")+(Setup!$B$9="Yes")*$M$8:$BT$8*($M12:$BT12=""))),"")) | K12: =IF($B12="","",IFERROR(SUMIFS($M12:$BT12,$M$6:$BT$6,K$9)/SUMPRODUCT(($M$6:$BT$6=K$9)*$M$7:$BT$7*(ISNUMBER($M12:$BT12)+($M12:$BT12="M")+(Setup!$B$9="Yes")*$M$8:$BT$8*($M12:$BT12=""))),"")) | L12: =IF($B12="","",IFERROR(SUMIFS($M12:$BT12,$M$6:$BT$6,L$9)/SUMPRODUCT(($M$6:$BT$6=L$9)*$M$7:$BT$7*(ISNUMBER($M12:$BT12)+($M12:$BT12="M")+(Setup!$B$9="Yes")*$M$8:$BT$8*($M12:$BT12=""))),"")) | M12: M | N12: 8.1 | O12: 19 | P12: 7.6 | Q12: 71 | R12: 7.4 | S12: 7 | T12: 16 | U12: 7.3 | V12: 78 | W12: 7.3 | X12: 7.8 | Y12: EX
A13: 4 | B13: =IF(Roster!B9="","",Roster!B9) | C13: =IF($B13="","",IFERROR(SUMPRODUCT($H$3:$L$3,H13:L13)/SUMPRODUCT($H$3:$L$3,--ISNUMBER(H13:L13)),"")) | D13: =IF(C13="","",VLOOKUP(C13,Setup!$D$12:$E$23,2,TRUE)) | E13: =IF($B13="","",IFERROR(SUMPRODUCT($M$8:$BT$8*ISNUMBER($M13:$BT13))/SUMPRODUCT($M$8:$BT$8*($M13:$BT13<>"EX")),"")) | F13: =IF($B13="","",SUMPRODUCT($M$8:$BT$8*($M13:$BT13=""))+COUNTIF($M13:$BT13,"M")) | G13: =IF($B13="","",IFERROR(SUM($M13:$BT13)/SUMPRODUCT($M$7:$BT$7*ISNUMBER($M13:$BT13)),"")) | H13: =IF($B13="","",IFERROR(SUMIFS($M13:$BT13,$M$6:$BT$6,H$9)/SUMPRODUCT(($M$6:$BT$6=H$9)*$M$7:$BT$7*(ISNUMBER($M13:$BT13)+($M13:$BT13="M")+(Setup!$B$9="Yes")*$M$8:$BT$8*($M13:$BT13=""))),"")) | I13: =IF($B13="","",IFERROR(SUMIFS($M13:$BT13,$M$6:$BT$6,I$9)/SUMPRODUCT(($M$6:$BT$6=I$9)*$M$7:$BT$7*(ISNUMBER($M13:$BT13)+($M13:$BT13="M")+(Setup!$B$9="Yes")*$M$8:$BT$8*($M13:$BT13=""))),"")) | J13: =IF($B13="","",IFERROR(SUMIFS($M13:$BT13,$M$6:$BT$6,J$9)/SUMPRODUCT(($M$6:$BT$6=J$9)*$M$7:$BT$7*(ISNUMBER($M13:$BT13)+($M13:$BT13="M")+(Setup!$B$9="Yes")*$M$8:$BT$8*($M13:$BT13=""))),"")) | K13: =IF($B13="","",IFERROR(SUMIFS($M13:$BT13,$M$6:$BT$6,K$9)/SUMPRODUCT(($M$6:$BT$6=K$9)*$M$7:$BT$7*(ISNUMBER($M13:$BT13)+($M13:$BT13="M")+(Setup!$B$9="Yes")*$M$8:$BT$8*($M13:$BT13=""))),"")) | L13: =IF($B13="","",IFERROR(SUMIFS($M13:$BT13,$M$6:$BT$6,L$9)/SUMPRODUCT(($M$6:$BT$6=L$9)*$M$7:$BT$7*(ISNUMBER($M13:$BT13)+($M13:$BT13="M")+(Setup!$B$9="Yes")*$M$8:$BT$8*($M13:$BT13=""))),"")) | M13: 8.5 | N13: 7 | O13: 19 | P13: 7.8 | Q13: EX | R13: 7.9 | S13: 7.9 | T13: M | U13: 8.8 | V13: 77 | W13: 7.8 | X13: 7.6 | Y13: 22
A14: 5 | B14: =IF(Roster!B10="","",Roster!B10) | C14: =IF($B14="","",IFERROR(SUMPRODUCT($H$3:$L$3,H14:L14)/SUMPRODUCT($H$3:$L$3,--ISNUMBER(H14:L14)),"")) | D14: =IF(C14="","",VLOOKUP(C14,Setup!$D$12:$E$23,2,TRUE)) | E14: =IF($B14="","",IFERROR(SUMPRODUCT($M$8:$BT$8*ISNUMBER($M14:$BT14))/SUMPRODUCT($M$8:$BT$8*($M14:$BT14<>"EX")),"")) | F14: =IF($B14="","",SUMPRODUCT($M$8:$BT$8*($M14:$BT14=""))+COUNTIF($M14:$BT14,"M")) | G14: =IF($B14="","",IFERROR(SUM($M14:$BT14)/SUMPRODUCT($M$7:$BT$7*ISNUMBER($M14:$BT14)),"")) | H14: =IF($B14="","",IFERROR(SUMIFS($M14:$BT14,$M$6:$BT$6,H$9)/SUMPRODUCT(($M$6:$BT$6=H$9)*$M$7:$BT$7*(ISNUMBER($M14:$BT14)+($M14:$BT14="M")+(Setup!$B$9="Yes")*$M$8:$BT$8*($M14:$BT14=""))),"")) | I14: =IF($B14="","",IFERROR(SUMIFS($M14:$BT14,$M$6:$BT$6,I$9)/SUMPRODUCT(($M$6:$BT$6=I$9)*$M$7:$BT$7*(ISNUMBER($M14:$BT14)+($M14:$BT14="M")+(Setup!$B$9="Yes")*$M$8:$BT$8*($M14:$BT14=""))),"")) | J14: =IF($B14="","",IFERROR(SUMIFS($M14:$BT14,$M$6:$BT$6,J$9)/SUMPRODUCT(($M$6:$BT$6=J$9)*$M$7:$BT$7*(ISNUMBER($M14:$BT14)+($M14:$BT14="M")+(Setup!$B$9="Yes")*$M$8:$BT$8*($M14:$BT14=""))),"")) | K14: =IF($B14="","",IFERROR(SUMIFS($M14:$BT14,$M$6:$BT$6,K$9)/SUMPRODUCT(($M$6:$BT$6=K$9)*$M$7:$BT$7*(ISNUMBER($M14:$BT14)+($M14:$BT14="M")+(Setup!$B$9="Yes")*$M$8:$BT$8*($M14:$BT14=""))),"")) | L14: =IF($B14="","",IFERROR(SUMIFS($M14:$BT14,$M$6:$BT$6,L$9)/SUMPRODUCT(($M$6:$BT$6=L$9)*$M$7:$BT$7*(ISNUMBER($M14:$BT14)+($M14:$BT14="M")+(Setup!$B$9="Yes")*$M$8:$BT$8*($M14:$BT14=""))),"")) | M14: 9.6 | N14: 9.9 | O14: 21 | P14: 10 | Q14: 97 | R14: 9.1 | S14: 9.6 | T14: 24 | U14: 9.2 | V14: 100 | W14: 9 | X14: 9.3 | Y14: 25
A15: 6 | B15: =IF(Roster!B11="","",Roster!B11) | C15: =IF($B15="","",IFERROR(SUMPRODUCT($H$3:$L$3,H15:L15)/SUMPRODUCT($H$3:$L$3,--ISNUMBER(H15:L15)),"")) | D15: =IF(C15="","",VLOOKUP(C15,Setup!$D$12:$E$23,2,TRUE)) | E15: =IF($B15="","",IFERROR(SUMPRODUCT($M$8:$BT$8*ISNUMBER($M15:$BT15))/SUMPRODUCT($M$8:$BT$8*($M15:$BT15<>"EX")),"")) | F15: =IF($B15="","",SUMPRODUCT($M$8:$BT$8*($M15:$BT15=""))+COUNTIF($M15:$BT15,"M")) | G15: =IF($B15="","",IFERROR(SUM($M15:$BT15)/SUMPRODUCT($M$7:$BT$7*ISNUMBER($M15:$BT15)),"")) | H15: =IF($B15="","",IFERROR(SUMIFS($M15:$BT15,$M$6:$BT$6,H$9)/SUMPRODUCT(($M$6:$BT$6=H$9)*$M$7:$BT$7*(ISNUMBER($M15:$BT15)+($M15:$BT15="M")+(Setup!$B$9="Yes")*$M$8:$BT$8*($M15:$BT15=""))),"")) | I15: =IF($B15="","",IFERROR(SUMIFS($M15:$BT15,$M$6:$BT$6,I$9)/SUMPRODUCT(($M$6:$BT$6=I$9)*$M$7:$BT$7*(ISNUMBER($M15:$BT15)+($M15:$BT15="M")+(Setup!$B$9="Yes")*$M$8:$BT$8*($M15:$BT15=""))),"")) | J15: =IF($B15="","",IFERROR(SUMIFS($M15:$BT15,$M$6:$BT$6,J$9)/SUMPRODUCT(($M$6:$BT$6=J$9)*$M$7:$BT$7*(ISNUMBER($M15:$BT15)+($M15:$BT15="M")+(Setup!$B$9="Yes")*$M$8:$BT$8*($M15:$BT15=""))),"")) | K15: =IF($B15="","",IFERROR(SUMIFS($M15:$BT15,$M$6:$BT$6,K$9)/SUMPRODUCT(($M$6:$BT$6=K$9)*$M$7:$BT$7*(ISNUMBER($M15:$BT15)+($M15:$BT15="M")+(Setup!$B$9="Yes")*$M$8:$BT$8*($M15:$BT15=""))),"")) | L15: =IF($B15="","",IFERROR(SUMIFS($M15:$BT15,$M$6:$BT$6,L$9)/SUMPRODUCT(($M$6:$BT$6=L$9)*$M$7:$BT$7*(ISNUMBER($M15:$BT15)+($M15:$BT15="M")+(Setup!$B$9="Yes")*$M$8:$BT$8*($M15:$BT15=""))),"")) | M15: 8.4 | N15: 9.2 | O15: 22 | P15: 8.8 | Q15: 84 | R15: 9.3 | S15: 9.4 | T15: 18 | U15: 9 | V15: 99 | W15: 8.5 | X15: EX | Y15: 22
A16: 7 | B16: =IF(Roster!B12="","",Roster!B12) | C16: =IF($B16="","",IFERROR(SUMPRODUCT($H$3:$L$3,H16:L16)/SUMPRODUCT($H$3:$L$3,--ISNUMBER(H16:L16)),"")) | D16: =IF(C16="","",VLOOKUP(C16,Setup!$D$12:$E$23,2,TRUE)) | E16: =IF($B16="","",IFERROR(SUMPRODUCT($M$8:$BT$8*ISNUMBER($M16:$BT16))/SUMPRODUCT($M$8:$BT$8*($M16:$BT16<>"EX")),"")) | F16: =IF($B16="","",SUMPRODUCT($M$8:$BT$8*($M16:$BT16=""))+COUNTIF($M16:$BT16,"M")) | G16: =IF($B16="","",IFERROR(SUM($M16:$BT16)/SUMPRODUCT($M$7:$BT$7*ISNUMBER($M16:$BT16)),"")) | H16: =IF($B16="","",IFERROR(SUMIFS($M16:$BT16,$M$6:$BT$6,H$9)/SUMPRODUCT(($M$6:$BT$6=H$9)*$M$7:$BT$7*(ISNUMBER($M16:$BT16)+($M16:$BT16="M")+(Setup!$B$9="Yes")*$M$8:$BT$8*($M16:$BT16=""))),"")) | I16: =IF($B16="","",IFERROR(SUMIFS($M16:$BT16,$M$6:$BT$6,I$9)/SUMPRODUCT(($M$6:$BT$6=I$9)*$M$7:$BT$7*(ISNUMBER($M16:$BT16)+($M16:$BT16="M")+(Setup!$B$9="Yes")*$M$8:$BT$8*($M16:$BT16=""))),"")) | J16: =IF($B16="","",IFERROR(SUMIFS($M16:$BT16,$M$6:$BT$6,J$9)/SUMPRODUCT(($M$6:$BT$6=J$9)*$M$7:$BT$7*(ISNUMBER($M16:$BT16)+($M16:$BT16="M")+(Setup!$B$9="Yes")*$M$8:$BT$8*($M16:$BT16=""))),"")) | K16: =IF($B16="","",IFERROR(SUMIFS($M16:$BT16,$M$6:$BT$6,K$9)/SUMPRODUCT(($M$6:$BT$6=K$9)*$M$7:$BT$7*(ISNUMBER($M16:$BT16)+($M16:$BT16="M")+(Setup!$B$9="Yes")*$M$8:$BT$8*($M16:$BT16=""))),"")) | L16: =IF($B16="","",IFERROR(SUMIFS($M16:$BT16,$M$6:$BT$6,L$9)/SUMPRODUCT(($M$6:$BT$6=L$9)*$M$7:$BT$7*(ISNUMBER($M16:$BT16)+($M16:$BT16="M")+(Setup!$B$9="Yes")*$M$8:$BT$8*($M16:$BT16=""))),"")) | M16: 9.7 | N16: 7.2 | O16: 20 | P16: 6.7 | Q16: 72 | R16: 7.7 | S16: 8.4 | T16: 22 | U16: 7 | V16: 89 | W16: 8 | X16: 8 | Y16: 17
A17: 8 | B17: =IF(Roster!B13="","",Roster!B13) | C17: =IF($B17="","",IFERROR(SUMPRODUCT($H$3:$L$3,H17:L17)/SUMPRODUCT($H$3:$L$3,--ISNUMBER(H17:L17)),"")) | D17: =IF(C17="","",VLOOKUP(C17,Setup!$D$12:$E$23,2,TRUE)) | E17: =IF($B17="","",IFERROR(SUMPRODUCT($M$8:$BT$8*ISNUMBER($M17:$BT17))/SUMPRODUCT($M$8:$BT$8*($M17:$BT17<>"EX")),"")) | F17: =IF($B17="","",SUMPRODUCT($M$8:$BT$8*($M17:$BT17=""))+COUNTIF($M17:$BT17,"M")) | G17: =IF($B17="","",IFERROR(SUM($M17:$BT17)/SUMPRODUCT($M$7:$BT$7*ISNUMBER($M17:$BT17)),"")) | H17: =IF($B17="","",IFERROR(SUMIFS($M17:$BT17,$M$6:$BT$6,H$9)/SUMPRODUCT(($M$6:$BT$6=H$9)*$M$7:$BT$7*(ISNUMBER($M17:$BT17)+($M17:$BT17="M")+(Setup!$B$9="Yes")*$M$8:$BT$8*($M17:$BT17=""))),"")) | I17: =IF($B17="","",IFERROR(SUMIFS($M17:$BT17,$M$6:$BT$6,I$9)/SUMPRODUCT(($M$6:$BT$6=I$9)*$M$7:$BT$7*(ISNUMBER($M17:$BT17)+($M17:$BT17="M")+(Setup!$B$9="Yes")*$M$8:$BT$8*($M17:$BT17=""))),"")) | J17: =IF($B17="","",IFERROR(SUMIFS($M17:$BT17,$M$6:$BT$6,J$9)/SUMPRODUCT(($M$6:$BT$6=J$9)*$M$7:$BT$7*(ISNUMBER($M17:$BT17)+($M17:$BT17="M")+(Setup!$B$9="Yes")*$M$8:$BT$8*($M17:$BT17=""))),"")) | K17: =IF($B17="","",IFERROR(SUMIFS($M17:$BT17,$M$6:$BT$6,K$9)/SUMPRODUCT(($M$6:$BT$6=K$9)*$M$7:$BT$7*(ISNUMBER($M17:$BT17)+($M17:$BT17="M")+(Setup!$B$9="Yes")*$M$8:$BT$8*($M17:$BT17=""))),"")) | L17: =IF($B17="","",IFERROR(SUMIFS($M17:$BT17,$M$6:$BT$6,L$9)/SUMPRODUCT(($M$6:$BT$6=L$9)*$M$7:$BT$7*(ISNUMBER($M17:$BT17)+($M17:$BT17="M")+(Setup!$B$9="Yes")*$M$8:$BT$8*($M17:$BT17=""))),"")) | M17: 7.9 | N17: 8.1 | O17: 18 | P17: 7.8 | Q17: 80 | R17: 7.1 | S17: 8.3 | T17: 17 | U17: M | V17: 83 | W17: 9 | X17: EX | Y17: 15
A18: 9 | B18: =IF(Roster!B14="","",Roster!B14) | C18: =IF($B18="","",IFERROR(SUMPRODUCT($H$3:$L$3,H18:L18)/SUMPRODUCT($H$3:$L$3,--ISNUMBER(H18:L18)),"")) | D18: =IF(C18="","",VLOOKUP(C18,Setup!$D$12:$E$23,2,TRUE)) | E18: =IF($B18="","",IFERROR(SUMPRODUCT($M$8:$BT$8*ISNUMBER($M18:$BT18))/SUMPRODUCT($M$8:$BT$8*($M18:$BT18<>"EX")),"")) | F18: =IF($B18="","",SUMPRODUCT($M$8:$BT$8*($M18:$BT18=""))+COUNTIF($M18:$BT18,"M")) | G18: =IF($B18="","",IFERROR(SUM($M18:$BT18)/SUMPRODUCT($M$7:$BT$7*ISNUMBER($M18:$BT18)),"")) | H18: =IF($B18="","",IFERROR(SUMIFS($M18:$BT18,$M$6:$BT$6,H$9)/SUMPRODUCT(($M$6:$BT$6=H$9)*$M$7:$BT$7*(ISNUMBER($M18:$BT18)+($M18:$BT18="M")+(Setup!$B$9="Yes")*$M$8:$BT$8*($M18:$BT18=""))),"")) | I18: =IF($B18="","",IFERROR(SUMIFS($M18:$BT18,$M$6:$BT$6,I$9)/SUMPRODUCT(($M$6:$BT$6=I$9)*$M$7:$BT$7*(ISNUMBER($M18:$BT18)+($M18:$BT18="M")+(Setup!$B$9="Yes")*$M$8:$BT$8*($M18:$BT18=""))),"")) | J18: =IF($B18="","",IFERROR(SUMIFS($M18:$BT18,$M$6:$BT$6,J$9)/SUMPRODUCT(($M$6:$BT$6=J$9)*$M$7:$BT$7*(ISNUMBER($M18:$BT18)+($M18:$BT18="M")+(Setup!$B$9="Yes")*$M$8:$BT$8*($M18:$BT18=""))),"")) | K18: =IF($B18="","",IFERROR(SUMIFS($M18:$BT18,$M$6:$BT$6,K$9)/SUMPRODUCT(($M$6:$BT$6=K$9)*$M$7:$BT$7*(ISNUMBER($M18:$BT18)+($M18:$BT18="M")+(Setup!$B$9="Yes")*$M$8:$BT$8*($M18:$BT18=""))),"")) | L18: =IF($B18="","",IFERROR(SUMIFS($M18:$BT18,$M$6:$BT$6,L$9)/SUMPRODUCT(($M$6:$BT$6=L$9)*$M$7:$BT$7*(ISNUMBER($M18:$BT18)+($M18:$BT18="M")+(Setup!$B$9="Yes")*$M$8:$BT$8*($M18:$BT18=""))),"")) | M18: 8.3 | N18: 7.7 | O18: 18 | P18: 7.3 | Q18: 84 | R18: 8.9 | S18: 6.8 | T18: 18 | U18: 8.8 | V18: M | W18: 8.4 | X18: 8.6 | Y18: 22
A19: 10 | B19: =IF(Roster!B15="","",Roster!B15) | C19: =IF($B19="","",IFERROR(SUMPRODUCT($H$3:$L$3,H19:L19)/SUMPRODUCT($H$3:$L$3,--ISNUMBER(H19:L19)),"")) | D19: =IF(C19="","",VLOOKUP(C19,Setup!$D$12:$E$23,2,TRUE)) | E19: =IF($B19="","",IFERROR(SUMPRODUCT($M$8:$BT$8*ISNUMBER($M19:$BT19))/SUMPRODUCT($M$8:$BT$8*($M19:$BT19<>"EX")),"")) | F19: =IF($B19="","",SUMPRODUCT($M$8:$BT$8*($M19:$BT19=""))+COUNTIF($M19:$BT19,"M")) | G19: =IF($B19="","",IFERROR(SUM($M19:$BT19)/SUMPRODUCT($M$7:$BT$7*ISNUMBER($M19:$BT19)),"")) | H19: =IF($B19="","",IFERROR(SUMIFS($M19:$BT19,$M$6:$BT$6,H$9)/SUMPRODUCT(($M$6:$BT$6=H$9)*$M$7:$BT$7*(ISNUMBER($M19:$BT19)+($M19:$BT19="M")+(Setup!$B$9="Yes")*$M$8:$BT$8*($M19:$BT19=""))),"")) | I19: =IF($B19="","",IFERROR(SUMIFS($M19:$BT19,$M$6:$BT$6,I$9)/SUMPRODUCT(($M$6:$BT$6=I$9)*$M$7:$BT$7*(ISNUMBER($M19:$BT19)+($M19:$BT19="M")+(Setup!$B$9="Yes")*$M$8:$BT$8*($M19:$BT19=""))),"")) | J19: =IF($B19="","",IFERROR(SUMIFS($M19:$BT19,$M$6:$BT$6,J$9)/SUMPRODUCT(($M$6:$BT$6=J$9)*$M$7:$BT$7*(ISNUMBER($M19:$BT19)+($M19:$BT19="M")+(Setup!$B$9="Yes")*$M$8:$BT$8*($M19:$BT19=""))),"")) | K19: =IF($B19="","",IFERROR(SUMIFS($M19:$BT19,$M$6:$BT$6,K$9)/SUMPRODUCT(($M$6:$BT$6=K$9)*$M$7:$BT$7*(ISNUMBER($M19:$BT19)+($M19:$BT19="M")+(Setup!$B$9="Yes")*$M$8:$BT$8*($M19:$BT19=""))),"")) | L19: =IF($B19="","",IFERROR(SUMIFS($M19:$BT19,$M$6:$BT$6,L$9)/SUMPRODUCT(($M$6:$BT$6=L$9)*$M$7:$BT$7*(ISNUMBER($M19:$BT19)+($M19:$BT19="M")+(Setup!$B$9="Yes")*$M$8:$BT$8*($M19:$BT19=""))),"")) | M19: 6.8 | N19: 8.1 | O19: 17 | P19: 7.3 | Q19: 78 | R19: EX | S19: 6.7 | T19: 21 | U19: 7.8 | V19: 70 | W19: 8 | X19: 7.9 | Y19: 18
A20: 11 | B20: =IF(Roster!B16="","",Roster!B16) | C20: =IF($B20="","",IFERROR(SUMPRODUCT($H$3:$L$3,H20:L20)/SUMPRODUCT($H$3:$L$3,--ISNUMBER(H20:L20)),"")) | D20: =IF(C20="","",VLOOKUP(C20,Setup!$D$12:$E$23,2,TRUE)) | E20: =IF($B20="","",IFERROR(SUMPRODUCT($M$8:$BT$8*ISNUMBER($M20:$BT20))/SUMPRODUCT($M$8:$BT$8*($M20:$BT20<>"EX")),"")) | F20: =IF($B20="","",SUMPRODUCT($M$8:$BT$8*($M20:$BT20=""))+COUNTIF($M20:$BT20,"M")) | G20: =IF($B20="","",IFERROR(SUM($M20:$BT20)/SUMPRODUCT($M$7:$BT$7*ISNUMBER($M20:$BT20)),"")) | H20: =IF($B20="","",IFERROR(SUMIFS($M20:$BT20,$M$6:$BT$6,H$9)/SUMPRODUCT(($M$6:$BT$6=H$9)*$M$7:$BT$7*(ISNUMBER($M20:$BT20)+($M20:$BT20="M")+(Setup!$B$9="Yes")*$M$8:$BT$8*($M20:$BT20=""))),"")) | I20: =IF($B20="","",IFERROR(SUMIFS($M20:$BT20,$M$6:$BT$6,I$9)/SUMPRODUCT(($M$6:$BT$6=I$9)*$M$7:$BT$7*(ISNUMBER($M20:$BT20)+($M20:$BT20="M")+(Setup!$B$9="Yes")*$M$8:$BT$8*($M20:$BT20=""))),"")) | J20: =IF($B20="","",IFERROR(SUMIFS($M20:$BT20,$M$6:$BT$6,J$9)/SUMPRODUCT(($M$6:$BT$6=J$9)*$M$7:$BT$7*(ISNUMBER($M20:$BT20)+($M20:$BT20="M")+(Setup!$B$9="Yes")*$M$8:$BT$8*($M20:$BT20=""))),"")) | K20: =IF($B20="","",IFERROR(SUMIFS($M20:$BT20,$M$6:$BT$6,K$9)/SUMPRODUCT(($M$6:$BT$6=K$9)*$M$7:$BT$7*(ISNUMBER($M20:$BT20)+($M20:$BT20="M")+(Setup!$B$9="Yes")*$M$8:$BT$8*($M20:$BT20=""))),"")) | L20: =IF($B20="","",IFERROR(SUMIFS($M20:$BT20,$M$6:$BT$6,L$9)/SUMPRODUCT(($M$6:$BT$6=L$9)*$M$7:$BT$7*(ISNUMBER($M20:$BT20)+($M20:$BT20="M")+(Setup!$B$9="Yes")*$M$8:$BT$8*($M20:$BT20=""))),"")) | M20: 10 | N20: 9.6 | O20: 25 | P20: 10 | Q20: 97 | R20: 9.9 | S20: 9.9 | T20: 24 | U20: 9.5 | V20: 100 | W20: 9.5 | X20: 10 | Y20: 21
A21: 12 | B21: =IF(Roster!B17="","",Roster!B17) | C21: =IF($B21="","",IFERROR(SUMPRODUCT($H$3:$L$3,H21:L21)/SUMPRODUCT($H$3:$L$3,--ISNUMBER(H21:L21)),"")) | D21: =IF(C21="","",VLOOKUP(C21,Setup!$D$12:$E$23,2,TRUE)) | E21: =IF($B21="","",IFERROR(SUMPRODUCT($M$8:$BT$8*ISNUMBER($M21:$BT21))/SUMPRODUCT($M$8:$BT$8*($M21:$BT21<>"EX")),"")) | F21: =IF($B21="","",SUMPRODUCT($M$8:$BT$8*($M21:$BT21=""))+COUNTIF($M21:$BT21,"M")) | G21: =IF($B21="","",IFERROR(SUM($M21:$BT21)/SUMPRODUCT($M$7:$BT$7*ISNUMBER($M21:$BT21)),"")) | H21: =IF($B21="","",IFERROR(SUMIFS($M21:$BT21,$M$6:$BT$6,H$9)/SUMPRODUCT(($M$6:$BT$6=H$9)*$M$7:$BT$7*(ISNUMBER($M21:$BT21)+($M21:$BT21="M")+(Setup!$B$9="Yes")*$M$8:$BT$8*($M21:$BT21=""))),"")) | I21: =IF($B21="","",IFERROR(SUMIFS($M21:$BT21,$M$6:$BT$6,I$9)/SUMPRODUCT(($M$6:$BT$6=I$9)*$M$7:$BT$7*(ISNUMBER($M21:$BT21)+($M21:$BT21="M")+(Setup!$B$9="Yes")*$M$8:$BT$8*($M21:$BT21=""))),"")) | J21: =IF($B21="","",IFERROR(SUMIFS($M21:$BT21,$M$6:$BT$6,J$9)/SUMPRODUCT(($M$6:$BT$6=J$9)*$M$7:$BT$7*(ISNUMBER($M21:$BT21)+($M21:$BT21="M")+(Setup!$B$9="Yes")*$M$8:$BT$8*($M21:$BT21=""))),"")) | K21: =IF($B21="","",IFERROR(SUMIFS($M21:$BT21,$M$6:$BT$6,K$9)/SUMPRODUCT(($M$6:$BT$6=K$9)*$M$7:$BT$7*(ISNUMBER($M21:$BT21)+($M21:$BT21="M")+(Setup!$B$9="Yes")*$M$8:$BT$8*($M21:$BT21=""))),"")) | L21: =IF($B21="","",IFERROR(SUMIFS($M21:$BT21,$M$6:$BT$6,L$9)/SUMPRODUCT(($M$6:$BT$6=L$9)*$M$7:$BT$7*(ISNUMBER($M21:$BT21)+($M21:$BT21="M")+(Setup!$B$9="Yes")*$M$8:$BT$8*($M21:$BT21=""))),"")) | M21: 6.8 | N21: 9.2 | O21: 21 | P21: 8.1 | Q21: 78 | R21: 8.8 | S21: 8.1 | T21: 20 | U21: 7.9 | V21: EX | W21: 8 | X21: 8.1 | Y21: 21
